Workbook

Sheet SKU Recommendations
A1: Category | B1: Workload | C1: Sub-workload / Notes | D1: Tier | E1: SKU | F1: Cores | G1: TDP (W) | H1: Base Freq | I1: All-Core Turbo | J1: Max Turbo | K1: Extra Freq / Notes | L1: Performance | M1: Why | N1: Core Type | O1: Platform / Memory Architecture | P1: Mem Channels | Q1: Base Freq (GHz) | R1: DDR5 RDIMM Speed Used (MT/s) | S1: DDR5 MRDIMM Speed Used (MT/s) | T1: Peak Mem BW – RDIMM (GB/s) | U1: Peak Mem BW – MRDIMM (GB/s) | V1: AVX-512 FP64 TFLOPS (peak, base clk) | W1: AVX-512 FP32 TFLOPS (peak, base clk) | X1: AMX BF16/FP16 TFLOPS (peak, base clk) | Y1: AMX INT8 TOPS (peak, base clk) | Z1: Formula / Source
A2: AI / Machine Learning | B2: Machine Learning | C2: Scikit, XGBoost | D2: Good | E2: 6724P | F2: 16 | G2: 210 | H2: 3.6G | I2: 4.2G | J2: 4.3G | L2: Up to 1.28x higher Scikit-learn multi-instance classical machine learning performance vs prior generation*** | M2: SKUs with the highest frequency are most likely to deliver enhanced AI performance; Key CPU characteristics - high single threaded performance, large cache and high memory bandwidth | N2: P-core (Granite Rapids) | O2: Xeon 6700/6500-series (Birch Stream SP), 8-ch | P2: 8 | Q2: 3.6 | R2: 6400 | S2: 8000 | T2: =P2*R2*Assumptions!$B$10/1000 -> 409.6 | U2: =IF(ISNUMBER(S2),P2*S2*Assumptions!$B$10/1000,"N/A") -> 512 | V2: =F2*Q2*IF(N2="E-core (Sierra Forest)",Assumptions!$B$8,Assumptions!$B$4)/1000 -> 1.8432 | W2: =F2*Q2*IF(N2="E-core (Sierra Forest)",Assumptions!$B$9,Assumptions!$B$5)/1000 -> 3.6864 | X2: =IF(N2="E-core (Sierra Forest)","N/A (no AMX)",F2*Q2*Assumptions!$B$6/1000) -> 58.9824 | Y2: =IF(N2="E-core (Sierra Forest)","N/A (no AMX)",F2*Q2*Assumptions!$B$7/1000) -> 117.9648 | Z2: Peak theoretical figures, not measured. See 'Assumptions & Sources' tab for constants, formulas, and citations.
A3: AI / Machine Learning | B3: Machine Learning | C3: Scikit, XGBoost | D3: Better | E3: 6737P | F3: 32 | G3: 270 | H3: 2.9G | I3: 4G | J3: 4G | L3: Up to 1.28x higher Scikit-learn multi-instance classical machine learning performance vs prior generation*** | M3: SKUs with the highest frequency are most likely to deliver enhanced AI performance; Key CPU characteristics - high single threaded performance, large cache and high memory bandwidth | N3: P-core (Granite Rapids) | O3: Xeon 6700/6500-series (Birch Stream SP), 8-ch | P3: 8 | Q3: 2.9 | R3: 6400 | S3: 8000 | T3: =P3*R3*Assumptions!$B$10/1000 -> 409.6 | U3: =IF(ISNUMBER(S3),P3*S3*Assumptions!$B$10/1000,"N/A") -> 512 | V3: =F3*Q3*IF(N3="E-core (Sierra Forest)",Assumptions!$B$8,Assumptions!$B$4)/1000 -> 2.9696 | W3: =F3*Q3*IF(N3="E-core (Sierra Forest)",Assumptions!$B$9,Assumptions!$B$5)/1000 -> 5.9392 | X3: =IF(N3="E-core (Sierra Forest)","N/A (no AMX)",F3*Q3*Assumptions!$B$6/1000) -> 95.0272 | Y3: =IF(N3="E-core (Sierra Forest)","N/A (no AMX)",F3*Q3*Assumptions!$B$7/1000) -> 190.0544 | Z3: Peak theoretical figures, not measured. See 'Assumptions & Sources' tab for constants, formulas, and citations.
A4: AI / Machine Learning | B4: Machine Learning | C4: Scikit, XGBoost | D4: Best | E4: 6960P | F4: 72 | G4: 500 | H4: 2.7G | I4: 3.8G | J4: 3.9G | L4: Up to 1.28x higher Scikit-learn multi-instance classical machine learning performance vs prior generation*** | M4: SKUs with the highest frequency are most likely to deliver enhanced AI performance; Key CPU characteristics - high single threaded performance, large cache and high memory bandwidth | N4: P-core (Granite Rapids) | O4: Xeon 6900-series (Birch Stream AP), 12-ch | P4: 12 | Q4: 2.7 | R4: 6400 | S4: 8800 | T4: =P4*R4*Assumptions!$B$10/1000 -> 614.4 | U4: =IF(ISNUMBER(S4),P4*S4*Assumptions!$B$10/1000,"N/A") -> 844.8 | V4: =F4*Q4*IF(N4="E-core (Sierra Forest)",Assumptions!$B$8,Assumptions!$B$4)/1000 -> 6.2208 | W4: =F4*Q4*IF(N4="E-core (Sierra Forest)",Assumptions!$B$9,Assumptions!$B$5)/1000 -> 12.4416 | X4: =IF(N4="E-core (Sierra Forest)","N/A (no AMX)",F4*Q4*Assumptions!$B$6/1000) -> 199.0656 | Y4: =IF(N4="E-core (Sierra Forest)","N/A (no AMX)",F4*Q4*Assumptions!$B$7/1000) -> 398.1312 | Z4: Peak theoretical figures, not measured. See 'Assumptions & Sources' tab for constants, formulas, and citations.
A5: AI / Machine Learning | B5: Computer Vision | C5: ResNet50, Vision Transformer, YOLO (batch inference) | D5: Good | E5: 6960P | F5: 72 | G5: 500 | H5: 2.7G | I5: 3.8G | J5: 3.9G | L5: Up to 2.17x higher ResNet-50 batch inference performance (int8) with Intel Xeon 6980P vs. AMD EPYC 9755 | M5: Greatest number of cores is optimal; Benefits from high AMX frequency; Key CPU characteristics - high core counts, SIMD instructions and low latency | N5: P-core (Granite Rapids) | O5: Xeon 6900-series (Birch Stream AP), 12-ch | P5: 12 | Q5: 2.7 | R5: 6400 | S5: 8800 | T5: =P5*R5*Assumptions!$B$10/1000 -> 614.4 | U5: =IF(ISNUMBER(S5),P5*S5*Assumptions!$B$10/1000,"N/A") -> 844.8 | V5: =F5*Q5*IF(N5="E-core (Sierra Forest)",Assumptions!$B$8,Assumptions!$B$4)/1000 -> 6.2208 | W5: =F5*Q5*IF(N5="E-core (Sierra Forest)",Assumptions!$B$9,Assumptions!$B$5)/1000 -> 12.4416 | X5: =IF(N5="E-core (Sierra Forest)","N/A (no AMX)",F5*Q5*Assumptions!$B$6/1000) -> 199.0656 | Y5: =IF(N5="E-core (Sierra Forest)","N/A (no AMX)",F5*Q5*Assumptions!$B$7/1000) -> 398.1312 | Z5: Peak theoretical figures, not measured. See 'Assumptions & Sources' tab for constants, formulas, and citations.
A6: AI / Machine Learning | B6: Computer Vision | C6: ResNet50, Vision Transformer, YOLO (batch inference) | D6: Better | E6: 6972P | F6: 96 | G6: 500 | H6: 2.4G | I6: 3.5G | J6: 3.9G | L6: Up to 2.17x higher ResNet-50 batch inference performance (int8) with Intel Xeon 6980P vs. AMD EPYC 9755 | M6: Greatest number of cores is optimal; Benefits from high AMX frequency; Key CPU characteristics - high core counts, SIMD instructions and low latency | N6: P-core (Granite Rapids) | O6: Xeon 6900-series (Birch Stream AP), 12-ch | P6: 12 | Q6: 2.4 | R6: 6400 | S6: 8800 | T6: =P6*R6*Assumptions!$B$10/1000 -> 614.4 | U6: =IF(ISNUMBER(S6),P6*S6*Assumptions!$B$10/1000,"N/A") -> 844.8 | V6: =F6*Q6*IF(N6="E-core (Sierra Forest)",Assumptions!$B$8,Assumptions!$B$4)/1000 -> 7.3728 | W6: =F6*Q6*IF(N6="E-core (Sierra Forest)",Assumptions!$B$9,Assumptions!$B$5)/1000 -> 14.7456 | X6: =IF(N6="E-core (Sierra Forest)","N/A (no AMX)",F6*Q6*Assumptions!$B$6/1000) -> 235.9296 | Y6: =IF(N6="E-core (Sierra Forest)","N/A (no AMX)",F6*Q6*Assumptions!$B$7/1000) -> 471.8592 | Z6: Peak theoretical figures, not measured. See 'Assumptions & Sources' tab for constants, formulas, and citations.
A7: AI / Machine Learning | B7: Computer Vision | C7: ResNet50, Vision Transformer, YOLO (batch inference) | D7: Best | E7: 6980P | F7: 128 | G7: 500 | H7: 2G | I7: 3.2G | J7: 3.9G | L7: Up to 2.17x higher ResNet-50 batch inference performance (int8) with Intel Xeon 6980P vs. AMD EPYC 9755 | M7: Greatest number of cores is optimal; Benefits from high AMX frequency; Key CPU characteristics - high core counts, SIMD instructions and low latency | N7: P-core (Granite Rapids) | O7: Xeon 6900-series (Birch Stream AP), 12-ch | P7: 12 | Q7: 2 | R7: 6400 | S7: 8800 | T7: =P7*R7*Assumptions!$B$10/1000 -> 614.4 | U7: =IF(ISNUMBER(S7),P7*S7*Assumptions!$B$10/1000,"N/A") -> 844.8 | V7: =F7*Q7*IF(N7="E-core (Sierra Forest)",Assumptions!$B$8,Assumptions!$B$4)/1000 -> 8.192 | W7: =F7*Q7*IF(N7="E-core (Sierra Forest)",Assumptions!$B$9,Assumptions!$B$5)/1000 -> 16.384 | X7: =IF(N7="E-core (Sierra Forest)","N/A (no AMX)",F7*Q7*Assumptions!$B$6/1000) -> 262.144 | Y7: =IF(N7="E-core (Sierra Forest)","N/A (no AMX)",F7*Q7*Assumptions!$B$7/1000) -> 524.288 | Z7: Peak theoretical figures, not measured. See 'Assumptions & Sources' tab for constants, formulas, and citations.
A8: AI / Machine Learning | B8: Computer Vision | C8: ResNet50, Vision Transformer, YOLO (real-time inference) | D8: Good | E8: 6747P | F8: 48 | G8: 330 | H8: 2.7G | I8: 3.8G | J8: 3.9G | L8: Up to 1.86x (int8) and 1.82x (bf16) higher ResNet-50 Real-Time Inference performance with Intel Xeon 6980P [MRDIMM] vs. prior generation | M8: Greatest number of cores is optimal; Benefits from high AMX frequency; Key CPU characteristics - high core counts, SIMD instructions and low latency | N8: P-core (Granite Rapids) | O8: Xeon 6700/6500-series (Birch Stream SP), 8-ch | P8: 8 | Q8: 2.7 | R8: 6400 | S8: 8000 | T8: =P8*R8*Assumptions!$B$10/1000 -> 409.6 | U8: =IF(ISNUMBER(S8),P8*S8*Assumptions!$B$10/1000,"N/A") -> 512 | V8: =F8*Q8*IF(N8="E-core (Sierra Forest)",Assumptions!$B$8,Assumptions!$B$4)/1000 -> 4.1472 | W8: =F8*Q8*IF(N8="E-core (Sierra Forest)",Assumptions!$B$9,Assumptions!$B$5)/1000 -> 8.2944 | X8: =IF(N8="E-core (Sierra Forest)","N/A (no AMX)",F8*Q8*Assumptions!$B$6/1000) -> 132.7104 | Y8: =IF(N8="E-core (Sierra Forest)","N/A (no AMX)",F8*Q8*Assumptions!$B$7/1000) -> 265.4208 | Z8: Peak theoretical figures, not measured. See 'Assumptions & Sources' tab for constants, formulas, and citations.
A9: AI / Machine Learning | B9: Computer Vision | C9: ResNet50, Vision Transformer, YOLO (real-time inference) | D9: Better | E9: 6767P | F9: 64 | G9: 350 | H9: 2.6G | I9: 3.6G | J9: 3.9G | L9: Up to 1.86x (int8) and 1.82x (bf16) higher ResNet-50 Real-Time Inference performance with Intel Xeon 6980P [MRDIMM] vs. prior generation | M9: Greatest number of cores is optimal; Benefits from high AMX frequency; Key CPU characteristics - high core counts, SIMD instructions and low latency | N9: P-core (Granite Rapids) | O9: Xeon 6700/6500-series (Birch Stream SP), 8-ch | P9: 8 | Q9: 2.6 | R9: 6400 | S9: 8000 | T9: =P9*R9*Assumptions!$B$10/1000 -> 409.6 | U9: =IF(ISNUMBER(S9),P9*S9*Assumptions!$B$10/1000,"N/A") -> 512 | V9: =F9*Q9*IF(N9="E-core (Sierra Forest)",Assumptions!$B$8,Assumptions!$B$4)/1000 -> 5.3248 | W9: =F9*Q9*IF(N9="E-core (Sierra Forest)",Assumptions!$B$9,Assumptions!$B$5)/1000 -> 10.6496 | X9: =IF(N9="E-core (Sierra Forest)","N/A (no AMX)",F9*Q9*Assumptions!$B$6/1000) -> 170.3936 | Y9: =IF(N9="E-core (Sierra Forest)","N/A (no AMX)",F9*Q9*Assumptions!$B$7/1000) -> 340.7872 | Z9: Peak theoretical figures, not measured. See 'Assumptions & Sources' tab for constants, formulas, and citations.
A10: AI / Machine Learning | B10: Computer Vision | C10: ResNet50, Vision Transformer, YOLO (real-time inference) | D10: Best | E10: 6787P | F10: 86 | G10: 350 | H10: 2G | I10: 3.2G | J10: 3.8G | L10: Up to 1.86x (int8) and 1.82x (bf16) higher ResNet-50 Real-Time Inference performance with Intel Xeon 6980P [MRDIMM] vs. prior generation | M10: Greatest number of cores is optimal; Benefits from high AMX frequency; Key CPU characteristics - high core counts, SIMD instructions and low latency | N10: P-core (Granite Rapids) | O10: Xeon 6700/6500-series (Birch Stream SP), 8-ch | P10: 8 | Q10: 2 | R10: 6400 | S10: 8000 | T10: =P10*R10*Assumptions!$B$10/1000 -> 409.6 | U10: =IF(ISNUMBER(S10),P10*S10*Assumptions!$B$10/1000,"N/A") -> 512 | V10: =F10*Q10*IF(N10="E-core (Sierra Forest)",Assumptions!$B$8,Assumptions!$B$4)/1000 -> 5.504 | W10: =F10*Q10*IF(N10="E-core (Sierra Forest)",Assumptions!$B$9,Assumptions!$B$5)/1000 -> 11.008 | X10: =IF(N10="E-core (Sierra Forest)","N/A (no AMX)",F10*Q10*Assumptions!$B$6/1000) -> 176.128 | Y10: =IF(N10="E-core (Sierra Forest)","N/A (no AMX)",F10*Q10*Assumptions!$B$7/1000) -> 352.256 | Z10: Peak theoretical figures, not measured. See 'Assumptions & Sources' tab for constants, formulas, and citations.
A11: AI / Machine Learning | B11: Natural Language Processing | C11: BERT (batch inference) | D11: Good | E11: 6960P | F11: 72 | G11: 500 | H11: 2.7G | I11: 3.8G | J11: 3.9G | L11: Up to 1.85x higher BERT-Large batch inference performance (int8) with Intel Xeon 6980P vs. AMD EPYC 9755 | M11: Greatest number of cores is optimal; Benefits from high AMX frequency; Key CPU characteristics - high core counts, SIMD instructions and low latency | N11: P-core (Granite Rapids) | O11: Xeon 6900-series (Birch Stream AP), 12-ch | P11: 12 | Q11: 2.7 | R11: 6400 | S11: 8800 | T11: =P11*R11*Assumptions!$B$10/1000 -> 614.4 | U11: =IF(ISNUMBER(S11),P11*S11*Assumptions!$B$10/1000,"N/A") -> 844.8 | V11: =F11*Q11*IF(N11="E-core (Sierra Forest)",Assumptions!$B$8,Assumptions!$B$4)/1000 -> 6.2208 | W11: =F11*Q11*IF(N11="E-core (Sierra Forest)",Assumptions!$B$9,Assumptions!$B$5)/1000 -> 12.4416 | X11: =IF(N11="E-core (Sierra Forest)","N/A (no AMX)",F11*Q11*Assumptions!$B$6/1000) -> 199.0656 | Y11: =IF(N11="E-core (Sierra Forest)","N/A (no AMX)",F11*Q11*Assumptions!$B$7/1000) -> 398.1312 | Z11: Peak theoretical figures, not measured. See 'Assumptions & Sources' tab for constants, formulas, and citations.
A12: AI / Machine Learning | B12: Natural Language Processing | C12: BERT (batch inference) | D12: Better | E12: 6972P | F12: 96 | G12: 500 | H12: 2.4G | I12: 3.5G | J12: 3.9G | L12: Up to 1.85x higher BERT-Large batch inference performance (int8) with Intel Xeon 6980P vs. AMD EPYC 9755 | M12: Greatest number of cores is optimal; Benefits from high AMX frequency; Key CPU characteristics - high core counts, SIMD instructions and low latency | N12: P-core (Granite Rapids) | O12: Xeon 6900-series (Birch Stream AP), 12-ch | P12: 12 | Q12: 2.4 | R12: 6400 | S12: 8800 | T12: =P12*R12*Assumptions!$B$10/1000 -> 614.4 | U12: =IF(ISNUMBER(S12),P12*S12*Assumptions!$B$10/1000,"N/A") -> 844.8 | V12: =F12*Q12*IF(N12="E-core (Sierra Forest)",Assumptions!$B$8,Assumptions!$B$4)/1000 -> 7.3728 | W12: =F12*Q12*IF(N12="E-core (Sierra Forest)",Assumptions!$B$9,Assumptions!$B$5)/1000 -> 14.7456 | X12: =IF(N12="E-core (Sierra Forest)","N/A (no AMX)",F12*Q12*Assumptions!$B$6/1000) -> 235.9296 | Y12: =IF(N12="E-core (Sierra Forest)","N/A (no AMX)",F12*Q12*Assumptions!$B$7/1000) -> 471.8592 | Z12: Peak theoretical figures, not measured. See 'Assumptions & Sources' tab for constants, formulas, and citations.
A13: AI / Machine Learning | B13: Natural Language Processing | C13: BERT (batch inference) | D13: Best | E13: 6980P | F13: 128 | G13: 500 | H13: 2G | I13: 3.2G | J13: 3.9G | L13: Up to 1.85x higher BERT-Large batch inference performance (int8) with Intel Xeon 6980P vs. AMD EPYC 9755 | M13: Greatest number of cores is optimal; Benefits from high AMX frequency; Key CPU characteristics - high core counts, SIMD instructions and low latency | N13: P-core (Granite Rapids) | O13: Xeon 6900-series (Birch Stream AP), 12-ch | P13: 12 | Q13: 2 | R13: 6400 | S13: 8800 | T13: =P13*R13*Assumptions!$B$10/1000 -> 614.4 | U13: =IF(ISNUMBER(S13),P13*S13*Assumptions!$B$10/1000,"N/A") -> 844.8 | V13: =F13*Q13*IF(N13="E-core (Sierra Forest)",Assumptions!$B$8,Assumptions!$B$4)/1000 -> 8.192 | W13: =F13*Q13*IF(N13="E-core (Sierra Forest)",Assumptions!$B$9,Assumptions!$B$5)/1000 -> 16.384 | X13: =IF(N13="E-core (Sierra Forest)","N/A (no AMX)",F13*Q13*Assumptions!$B$6/1000) -> 262.144 | Y13: =IF(N13="E-core (Sierra Forest)","N/A (no AMX)",F13*Q13*Assumptions!$B$7/1000) -> 524.288 | Z13: Peak theoretical figures, not measured. See 'Assumptions & Sources' tab for constants, formulas, and citations.
... A32: HPC / Simulation | B32: Manufacturing / Simulation | C32: OpenFOAM, Fluent, Dyna | D32: Best | E32: 6972P | F32: 96 | G32: 500 | H32: 2.4G | I32: 3.5G | J32: 3.8G | L32: Intel Xeon 6980P delivers 1.43x higher performance and 1.34x higher performance/watt per server vs. Intel Xeon AMD EPYC 9755 on OpenFOAM geomean (2); Up to 2.43x higher OpenFOAM performance and up to 1.7x higher OpenFOAM perf/watt with Intel Xeon 6980P (MRDIMM) vs. Intel Xeon 8592+ | M32: High memory bandwidth (MRDIMMs) recommended for best performance | N32: P-core (Granite Rapids) | O32: Xeon 6900-series (Birch Stream AP), 12-ch | P32: 12 | Q32: 2.4 | R32: 6400 | S32: 8800 | T32: =P32*R32*Assumptions!$B$10/1000 -> 614.4 | U32: =IF(ISNUMBER(S32),P32*S32*Assumptions!$B$10/1000,"N/A") -> 844.8 | V32: =F32*Q32*IF(N32="E-core (Sierra Forest)",Assumptions!$B$8,Assumptions!$B$4)/1000 -> 7.3728 | W32: =F32*Q32*IF(N32="E-core (Sierra Forest)",Assumptions!$B$9,Assumptions!$B$5)/1000 -> 14.7456 | X32: =IF(N32="E-core (Sierra Forest)","N/A (no AMX)",F32*Q32*Assumptions!$B$6/1000) -> 235.9296 | Y32: =IF(N32="E-core (Sierra Forest)","N/A (no AMX)",F32*Q32*Assumptions!$B$7/1000) -> 471.8592 | Z32: Peak theoretical figures, not measured. See 'Assumptions & Sources' tab for constants, formulas, and citations.
A33: HPC / Simulation | B33: Manufacturing / Simulation | C33: OpenFOAM, Fluent, Dyna | D33: Best | E33: 6960P* | F33: 72 | G33: 500 | H33: 2.7G | I33: 3.8G | J33: 3.9G | K33: also 66C/48C variants | L33: Intel Xeon 6980P delivers 1.43x higher performance and 1.34x higher performance/watt per server vs. Intel Xeon AMD EPYC 9755 on OpenFOAM geomean (2); Up to 2.43x higher OpenFOAM performance and up to 1.7x higher OpenFOAM perf/watt with Intel Xeon 6980P (MRDIMM) vs. Intel Xeon 8592+ | M33: High memory bandwidth (MRDIMMs) recommended for best performance | N33: P-core (Granite Rapids) | O33: Xeon 6900-series (Birch Stream AP), 12-ch | P33: 12 | Q33: 2.7 | R33: 6400 | S33: 8800 | T33: =P33*R33*Assumptions!$B$10/1000 -> 614.4 | U33: =IF(ISNUMBER(S33),P33*S33*Assumptions!$B$10/1000,"N/A") -> 844.8 | V33: =F33*Q33*IF(N33="E-core (Sierra Forest)",Assumptions!$B$8,Assumptions!$B$4)/1000 -> 6.2208 | W33: =F33*Q33*IF(N33="E-core (Sierra Forest)",Assumptions!$B$9,Assumptions!$B$5)/1000 -> 12.4416 | X33: =IF(N33="E-core (Sierra Forest)","N/A (no AMX)",F33*Q33*Assumptions!$B$6/1000) -> 199.0656 | Y33: =IF(N33="E-core (Sierra Forest)","N/A (no AMX)",F33*Q33*Assumptions!$B$7/1000) -> 398.1312 | Z33: Peak theoretical figures, not measured. See 'Assumptions & Sources' tab for constants, formulas, and citations.
A34: HPC / Simulation | B34: Energy | C34: Seismic Kernal | D34: Good | E34: 6767P | F34: 64 | G34: 350 | H34: 2.4G | I34: 3.6G | J34: 3.9G | L34: Up to 1.54x higher Seismic Kernels (geomean of 4) performance with Intel Xeon 6980P (MRDIMM) vs. AMD EPYC 9654 | M34: High memory bandwidth (MRDIMMs) recommended for best performance; Benefit from higher core counts | N34: P-core (Granite Rapids) | O34: Xeon 6700/6500-series (Birch Stream SP), 8-ch | P34: 8 | Q34: 2.4 | R34: 6400 | S34: 8000 | T34: =P34*R34*Assumptions!$B$10/1000 -> 409.6 | U34: =IF(ISNUMBER(S34),P34*S34*Assumptions!$B$10/1000,"N/A") -> 512 | V34: =F34*Q34*IF(N34="E-core (Sierra Forest)",Assumptions!$B$8,Assumptions!$B$4)/1000 -> 4.9152 | W34: =F34*Q34*IF(N34="E-core (Sierra Forest)",Assumptions!$B$9,Assumptions!$B$5)/1000 -> 9.8304 | X34: =IF(N34="E-core (Sierra Forest)","N/A (no AMX)",F34*Q34*Assumptions!$B$6/1000) -> 157.2864 | Y34: =IF(N34="E-core (Sierra Forest)","N/A (no AMX)",F34*Q34*Assumptions!$B$7/1000) -> 314.5728 | Z34: Peak theoretical figures, not measured. See 'Assumptions & Sources' tab for constants, formulas, and citations.
A35: HPC / Simulation | B35: Energy | C35: Seismic Kernal | D35: Better | E35: 6972P | F35: 96 | G35: 500 | H35: 2.4G | I35: 3.5G | J35: 3.9G | L35: Up to 1.54x higher Seismic Kernels (geomean of 4) performance with Intel Xeon 6980P (MRDIMM) vs. AMD EPYC 9654 | M35: High memory bandwidth (MRDIMMs) recommended for best performance; Benefit from higher core counts | N35: P-core (Granite Rapids) | O35: Xeon 6900-series (Birch Stream AP), 12-ch | P35: 12 | Q35: 2.4 | R35: 6400 | S35: 8800 | T35: =P35*R35*Assumptions!$B$10/1000 -> 614.4 | U35: =IF(ISNUMBER(S35),P35*S35*Assumptions!$B$10/1000,"N/A") -> 844.8 | V35: =F35*Q35*IF(N35="E-core (Sierra Forest)",Assumptions!$B$8,Assumptions!$B$4)/1000 -> 7.3728 | W35: =F35*Q35*IF(N35="E-core (Sierra Forest)",Assumptions!$B$9,Assumptions!$B$5)/1000 -> 14.7456 | X35: =IF(N35="E-core (Sierra Forest)","N/A (no AMX)",F35*Q35*Assumptions!$B$6/1000) -> 235.9296 | Y35: =IF(N35="E-core (Sierra Forest)","N/A (no AMX)",F35*Q35*Assumptions!$B$7/1000) -> 471.8592 | Z35: Peak theoretical figures, not measured. See 'Assumptions & Sources' tab for constants, formulas, and citations.
A36: HPC / Simulation | B36: Energy | C36: Seismic Kernal | D36: Better | E36: 6787P | F36: 86 | G36: 350 | H36: 2G | I36: 3.2G | J36: 3.8G | L36: Up to 1.54x higher Seismic Kernels (geomean of 4) performance with Intel Xeon 6980P (MRDIMM) vs. AMD EPYC 9654 | M36: High memory bandwidth (MRDIMMs) recommended for best performance; Benefit from higher core counts | N36: P-core (Granite Rapids) | O36: Xeon 6700/6500-series (Birch Stream SP), 8-ch | P36: 8 | Q36: 2 | R36: 6400 | S36: 8000 | T36: =P36*R36*Assumptions!$B$10/1000 -> 409.6 | U36: =IF(ISNUMBER(S36),P36*S36*Assumptions!$B$10/1000,"N/A") -> 512 | V36: =F36*Q36*IF(N36="E-core (Sierra Forest)",Assumptions!$B$8,Assumptions!$B$4)/1000 -> 5.504 | W36: =F36*Q36*IF(N36="E-core (Sierra Forest)",Assumptions!$B$9,Assumptions!$B$5)/1000 -> 11.008 | X36: =IF(N36="E-core (Sierra Forest)","N/A (no AMX)",F36*Q36*Assumptions!$B$6/1000) -> 176.128 | Y36: =IF(N36="E-core (Sierra Forest)","N/A (no AMX)",F36*Q36*Assumptions!$B$7/1000) -> 352.256 | Z36: Peak theoretical figures, not measured. See 'Assumptions & Sources' tab for constants, formulas, and citations.
A37: HPC / Simulation | B37: Energy | C37: Seismic Kernal | D37: Best | E37: 6980P | F37: 128 | G37: 500 | H37: 2G | I37: 3.2G | J37: 3.9G | L37: Up to 1.54x higher Seismic Kernels (geomean of 4) performance with Intel Xeon 6980P (MRDIMM) vs. AMD EPYC 9654 | M37: High memory bandwidth (MRDIMMs) recommended for best performance; Benefit from higher core counts | N37: P-core (Granite Rapids) | O37: Xeon 6900-series (Birch Stream AP), 12-ch | P37: 12 | Q37: 2 | R37: 6400 | S37: 8800 | T37: =P37*R37*Assumptions!$B$10/1000 -> 614.4 | U37: =IF(ISNUMBER(S37),P37*S37*Assumptions!$B$10/1000,"N/A") -> 844.8 | V37: =F37*Q37*IF(N37="E-core (Sierra Forest)",Assumptions!$B$8,Assumptions!$B$4)/1000 -> 8.192 | W37: =F37*Q37*IF(N37="E-core (Sierra Forest)",Assumptions!$B$9,Assumptions!$B$5)/1000 -> 16.384 | X37: =IF(N37="E-core (Sierra Forest)","N/A (no AMX)",F37*Q37*Assumptions!$B$6/1000) -> 262.144 | Y37: =IF(N37="E-core (Sierra Forest)","N/A (no AMX)",F37*Q37*Assumptions!$B$7/1000) -> 524.288 | Z37: Peak theoretical figures, not measured. See 'Assumptions & Sources' tab for constants, formulas, and citations.
A38: HPC / Simulation | B38: Energy | C38: Seismic Kernal | D38: Best | E38: 6978P | F38: 120 | G38: 500 | H38: 2.1G | I38: 3.2G | J38: 3.9G | L38: Up to 1.54x higher Seismic Kernels (geomean of 4) performance with Intel Xeon 6980P (MRDIMM) vs. AMD EPYC 9654 | M38: High memory bandwidth (MRDIMMs) recommended for best performance; Benefit from higher core counts | N38: P-core (Granite Rapids) | O38: Xeon 6900-series (Birch Stream AP), 12-ch | P38: 12 | Q38: 2.1 | R38: 6400 | S38: 8800 | T38: =P38*R38*Assumptions!$B$10/1000 -> 614.4 | U38: =IF(ISNUMBER(S38),P38*S38*Assumptions!$B$10/1000,"N/A") -> 844.8 | V38: =F38*Q38*IF(N38="E-core (Sierra Forest)",Assumptions!$B$8,Assumptions!$B$4)/1000 -> 8.064 | W38: =F38*Q38*IF(N38="E-core (Sierra Forest)",Assumptions!$B$9,Assumptions!$B$5)/1000 -> 16.128 | X38: =IF(N38="E-core (Sierra Forest)","N/A (no AMX)",F38*Q38*Assumptions!$B$6/1000) -> 258.048 | Y38: =IF(N38="E-core (Sierra Forest)","N/A (no AMX)",F38*Q38*Assumptions!$B$7/1000) -> 516.096 | Z38: Peak theoretical figures, not measured. See 'Assumptions & Sources' tab for constants, formulas, and citations.
A39: HPC / Simulation | B39: Numerical Weather Simulation | C39: NWS | D39: Good | E39: 6747P | F39: 48 | G39: 330 | H39: 2.7G | I39: 3.8G | J39: 3.9G | L39: Up to 2.17x better performance on Intel Xeon 6980P Processor (MRDIMM) compared to Intel Xeon Platinum 8592+ Processor (64C) on GFS C384 (Weather Forecast Performance) | M39: High memory bandwidth (MRDIMMs) recommended for best performance; Large cache sizes | N39: P-core (Granite Rapids) | O39: Xeon 6700/6500-series (Birch Stream SP), 8-ch | P39: 8 | Q39: 2.7 | R39: 6400 | S39: 8000 | T39: =P39*R39*Assumptions!$B$10/1000 -> 409.6 | U39: =IF(ISNUMBER(S39),P39*S39*Assumptions!$B$10/1000,"N/A") -> 512 | V39: =F39*Q39*IF(N39="E-core (Sierra Forest)",Assumptions!$B$8,Assumptions!$B$4)/1000 -> 4.1472 | W39: =F39*Q39*IF(N39="E-core (Sierra Forest)",Assumptions!$B$9,Assumptions!$B$5)/1000 -> 8.2944 | X39: =IF(N39="E-core (Sierra Forest)","N/A (no AMX)",F39*Q39*Assumptions!$B$6/1000) -> 132.7104 | Y39: =IF(N39="E-core (Sierra Forest)","N/A (no AMX)",F39*Q39*Assumptions!$B$7/1000) -> 265.4208 | Z39: Peak theoretical figures, not measured. See 'Assumptions & Sources' tab for constants, formulas, and citations.
A40: HPC / Simulation | B40: Numerical Weather Simulation | C40: NWS | D40: Better | E40: 6787P | F40: 86 | G40: 350 | H40: 2G | I40: 3.2G | J40: 3.8G | L40: Up to 2.17x better performance on Intel Xeon 6980P Processor (MRDIMM) compared to Intel Xeon Platinum 8592+ Processor (64C) on GFS C384 (Weather Forecast Performance) | M40: High memory bandwidth (MRDIMMs) recommended for best performance; Large cache sizes | N40: P-core (Granite Rapids) | O40: Xeon 6700/6500-series (Birch Stream SP), 8-ch | P40: 8 | Q40: 2 | R40: 6400 | S40: 8000 | T40: =P40*R40*Assumptions!$B$10/1000 -> 409.6 | U40: =IF(ISNUMBER(S40),P40*S40*Assumptions!$B$10/1000,"N/A") -> 512 | V40: =F40*Q40*IF(N40="E-core (Sierra Forest)",Assumptions!$B$8,Assumptions!$B$4)/1000 -> 5.504 | W40: =F40*Q40*IF(N40="E-core (Sierra Forest)",Assumptions!$B$9,Assumptions!$B$5)/1000 -> 11.008 | X40: =IF(N40="E-core (Sierra Forest)","N/A (no AMX)",F40*Q40*Assumptions!$B$6/1000) -> 176.128 | Y40: =IF(N40="E-core (Sierra Forest)","N/A (no AMX)",F40*Q40*Assumptions!$B$7/1000) -> 352.256 | Z40: Peak theoretical figures, not measured. See 'Assumptions & Sources' tab for constants, formulas, and citations.
A41: HPC / Simulation | B41: Numerical Weather Simulation | C41: NWS | D41: Better | E41: 6767P | F41: 64 | G41: 350 | H41: 2.4G | I41: 3.6G | J41: 3.9G | L41: Up to 2.17x better performance on Intel Xeon 6980P Processor (MRDIMM) compared to Intel Xeon Platinum 8592+ Processor (64C) on GFS C384 (Weather Forecast Performance) | M41: High memory bandwidth (MRDIMMs) recommended for best performance; Large cache sizes | N41: P-core (Granite Rapids) | O41: Xeon 6700/6500-series (Birch Stream SP), 8-ch | P41: 8 | Q41: 2.4 | R41: 6400 | S41: 8000 | T41: =P41*R41*Assumptions!$B$10/1000 -> 409.6 | U41: =IF(ISNUMBER(S41),P41*S41*Assumptions!$B$10/1000,"N/A") -> 512 | V41: =F41*Q41*IF(N41="E-core (Sierra Forest)",Assumptions!$B$8,Assumptions!$B$4)/1000 -> 4.9152 | W41: =F41*Q41*IF(N41="E-core (Sierra Forest)",Assumptions!$B$9,Assumptions!$B$5)/1000 -> 9.8304 | X41: =IF(N41="E-core (Sierra Forest)","N/A (no AMX)",F41*Q41*Assumptions!$B$6/1000) -> 157.2864 | Y41: =IF(N41="E-core (Sierra Forest)","N/A (no AMX)",F41*Q41*Assumptions!$B$7/1000) -> 314.5728 | Z41: Peak theoretical figures, not measured. See 'Assumptions & Sources' tab for constants, formulas, and citations.
A42: HPC / Simulation | B42: Numerical Weather Simulation | C42: NWS | D42: Best | E42: 6980P | F42: 128 | G42: 500 | H42: 2G | I42: 3.2G | J42: 3.9G | L42: Up to 2.17x better performance on Intel Xeon 6980P Processor (MRDIMM) compared to Intel Xeon Platinum 8592+ Processor (64C) on GFS C384 (Weather Forecast Performance) | M42: High memory bandwidth (MRDIMMs) recommended for best performance; Large cache sizes | N42: P-core (Granite Rapids) | O42: Xeon 6900-series (Birch Stream AP), 12-ch | P42: 12 | Q42: 2 | R42: 6400 | S42: 8800 | T42: =P42*R42*Assumptions!$B$10/1000 -> 614.4 | U42: =IF(ISNUMBER(S42),P42*S42*Assumptions!$B$10/1000,"N/A") -> 844.8 | V42: =F42*Q42*IF(N42="E-core (Sierra Forest)",Assumptions!$B$8,Assumptions!$B$4)/1000 -> 8.192 | W42: =F42*Q42*IF(N42="E-core (Sierra Forest)",Assumptions!$B$9,Assumptions!$B$5)/1000 -> 16.384 | X42: =IF(N42="E-core (Sierra Forest)","N/A (no AMX)",F42*Q42*Assumptions!$B$6/1000) -> 262.144 | Y42: =IF(N42="E-core (Sierra Forest)","N/A (no AMX)",F42*Q42*Assumptions!$B$7/1000) -> 524.288 | Z42: Peak theoretical figures, not measured. See 'Assumptions & Sources' tab for constants, formulas, and citations.
A43: HPC / Simulation | B43: Numerical Weather Simulation | C43: NWS | D43: Best | E43: 6972P | F43: 96 | G43: 500 | H43: 2.4G | I43: 3.5G | J43: 3.9G | L43: Up to 2.17x better performance on Intel Xeon 6980P Processor (MRDIMM) compared to Intel Xeon Platinum 8592+ Processor (64C) on GFS C384 (Weather Forecast Performance) | M43: High memory bandwidth (MRDIMMs) recommended for best performance; Large cache sizes | N43: P-core (Granite Rapids) | O43: Xeon 6900-series (Birch Stream AP), 12-ch | P43: 12 | Q43: 2.4 | R43: 6400 | S43: 8800 | T43: =P43*R43*Assumptions!$B$10/1000 -> 614.4 | U43: =IF(ISNUMBER(S43),P43*S43*Assumptions!$B$10/1000,"N/A") -> 844.8 | V43: =F43*Q43*IF(N43="E-core (Sierra Forest)",Assumptions!$B$8,Assumptions!$B$4)/1000 -> 7.3728 | W43: =F43*Q43*IF(N43="E-core (Sierra Forest)",Assumptions!$B$9,Assumptions!$B$5)/1000 -> 14.7456 | X43: =IF(N43="E-core (Sierra Forest)","N/A (no AMX)",F43*Q43*Assumptions!$B$6/1000) -> 235.9296 | Y43: =IF(N43="E-core (Sierra Forest)","N/A (no AMX)",F43*Q43*Assumptions!$B$7/1000) -> 471.8592 | Z43: Peak theoretical figures, not measured. See 'Assumptions & Sources' tab for constants, formulas, and citations.
A44: HPC / Simulation | B44: EDA | C44: Electronic Design Automation | D44: Good | E44: 6724P | F44: 16 | G44: 210 | H44: 3.6G | I44: 4.2G | J44: 4.3G | M44: Successful with lower core count CPUs; Benefits from higher frequency CPUs | N44: P-core (Granite Rapids) | O44: Xeon 6700/6500-series (Birch Stream SP), 8-ch | P44: 8 | Q44: 3.6 | R44: 6400 | S44: 8000 | T44: =P44*R44*Assumptions!$B$10/1000 -> 409.6 | U44: =IF(ISNUMBER(S44),P44*S44*Assumptions!$B$10/1000,"N/A") -> 512 | V44: =F44*Q44*IF(N44="E-core (Sierra Forest)",Assumptions!$B$8,Assumptions!$B$4)/1000 -> 1.8432 | W44: =F44*Q44*IF(N44="E-core (Sierra Forest)",Assumptions!$B$9,Assumptions!$B$5)/1000 -> 3.6864 | X44: =IF(N44="E-core (Sierra Forest)","N/A (no AMX)",F44*Q44*Assumptions!$B$6/1000) -> 58.9824 | Y44: =IF(N44="E-core (Sierra Forest)","N/A (no AMX)",F44*Q44*Assumptions!$B$7/1000) -> 117.9648 | Z44: Peak theoretical figures, not measured. See 'Assumptions & Sources' tab for constants, formulas, and citations.
A45: HPC / Simulation | B45: EDA | C45: Electronic Design Automation | D45: Better | E45: 6738P | F45: 32 | G45: 270 | H45: 2.9G | I45: 4.2G | J45: 4.2G | M45: Successful with lower core count CPUs; Benefits from higher frequency CPUs | N45: P-core (Granite Rapids) | O45: Xeon 6700/6500-series (Birch Stream SP), 8-ch | P45: 8 | Q45: 2.9 | R45: 6400 | S45: 8000 | T45: =P45*R45*Assumptions!$B$10/1000 -> 409.6 | U45: =IF(ISNUMBER(S45),P45*S45*Assumptions!$B$10/1000,"N/A") -> 512 | V45: =F45*Q45*IF(N45="E-core (Sierra Forest)",Assumptions!$B$8,Assumptions!$B$4)/1000 -> 2.9696 | W45: =F45*Q45*IF(N45="E-core (Sierra Forest)",Assumptions!$B$9,Assumptions!$B$5)/1000 -> 5.9392 | X45: =IF(N45="E-core (Sierra Forest)","N/A (no AMX)",F45*Q45*Assumptions!$B$6/1000) -> 95.0272 | Y45: =IF(N45="E-core (Sierra Forest)","N/A (no AMX)",F45*Q45*Assumptions!$B$7/1000) -> 190.0544 | Z45: Peak theoretical figures, not measured. See 'Assumptions & Sources' tab for constants, formulas, and citations.
A46: HPC / Simulation | B46: EDA | C46: Electronic Design Automation | D46: Best | E46: 6745P | F46: 32 | G46: 300 | H46: 3.1G | I46: 4.1G | J46: 4.3G | M46: Successful with lower core count CPUs; Benefits from higher frequency CPUs | N46: P-core (Granite Rapids) | O46: Xeon 6700/6500-series (Birch Stream SP), 8-ch | P46: 8 | Q46: 3.1 | R46: 6400 | S46: 8000 | T46: =P46*R46*Assumptions!$B$10/1000 -> 409.6 | U46: =IF(ISNUMBER(S46),P46*S46*Assumptions!$B$10/1000,"N/A") -> 512 | V46: =F46*Q46*IF(N46="E-core (Sierra Forest)",Assumptions!$B$8,Assumptions!$B$4)/1000 -> 3.1744 | W46: =F46*Q46*IF(N46="E-core (Sierra Forest)",Assumptions!$B$9,Assumptions!$B$5)/1000 -> 6.3488 | X46: =IF(N46="E-core (Sierra Forest)","N/A (no AMX)",F46*Q46*Assumptions!$B$6/1000) -> 101.5808 | Y46: =IF(N46="E-core (Sierra Forest)","N/A (no AMX)",F46*Q46*Assumptions!$B$7/1000) -> 203.1616 | Z46: Peak theoretical figures, not measured. See 'Assumptions & Sources' tab for constants, formulas, and citations.
A47: Database | B47: SQL Database | C47: MySQL / relational | D47: Good | E47: 6747P | F47: 48 | G47: 330 | H47: 2.7G | I47: 3.8G | J47: 3.9G | L47: Up to 1.32x higher MySQL performance with Intel Xeon 6787P vs. Intel Xeon 8592+ | M47: High memory capacity recommended for best performance; Target lower TDP, for ideal TCO result; Intel Xeon 6 with E-cores preferred if highest performance per watt is required vs. highest performance; Ideal recommendation of lower core count SKUs with good frequency | N47: P-core (Granite Rapids) | O47: Xeon 6700/6500-series (Birch Stream SP), 8-ch | P47: 8 | Q47: 2.7 | R47: 6400 | S47: 8000 | T47: =P47*R47*Assumptions!$B$10/1000 -> 409.6 | U47: =IF(ISNUMBER(S47),P47*S47*Assumptions!$B$10/1000,"N/A") -> 512 | V47: =F47*Q47*IF(N47="E-core (Sierra Forest)",Assumptions!$B$8,Assumptions!$B$4)/1000 -> 4.1472 | W47: =F47*Q47*IF(N47="E-core (Sierra Forest)",Assumptions!$B$9,Assumptions!$B$5)/1000 -> 8.2944 | X47: =IF(N47="E-core (Sierra Forest)","N/A (no AMX)",F47*Q47*Assumptions!$B$6/1000) -> 132.7104 | Y47: =IF(N47="E-core (Sierra Forest)","N/A (no AMX)",F47*Q47*Assumptions!$B$7/1000) -> 265.4208 | Z47: Peak theoretical figures, not measured. See 'Assumptions & Sources' tab for constants, formulas, and citations.
A48: Database | B48: SQL Database | C48: MySQL / relational | D48: Good | E48: 6737P | F48: 32 | G48: 270 | H48: 2.9G | I48: 4G | J48: 4G | L48: Up to 1.32x higher MySQL performance with Intel Xeon 6787P vs. Intel Xeon 8592+ | M48: High memory capacity recommended for best performance; Target lower TDP, for ideal TCO result; Intel Xeon 6 with E-cores preferred if highest performance per watt is required vs. highest performance; Ideal recommendation of lower core count SKUs with good frequency | N48: P-core (Granite Rapids) | O48: Xeon 6700/6500-series (Birch Stream SP), 8-ch | P48: 8 | Q48: 2.9 | R48: 6400 | S48: 8000 | T48: =P48*R48*Assumptions!$B$10/1000 -> 409.6 | U48: =IF(ISNUMBER(S48),P48*S48*Assumptions!$B$10/1000,"N/A") -> 512 | V48: =F48*Q48*IF(N48="E-core (Sierra Forest)",Assumptions!$B$8,Assumptions!$B$4)/1000 -> 2.9696 | W48: =F48*Q48*IF(N48="E-core (Sierra Forest)",Assumptions!$B$9,Assumptions!$B$5)/1000 -> 5.9392 | X48: =IF(N48="E-core (Sierra Forest)","N/A (no AMX)",F48*Q48*Assumptions!$B$6/1000) -> 95.0272 | Y48: =IF(N48="E-core (Sierra Forest)","N/A (no AMX)",F48*Q48*Assumptions!$B$7/1000) -> 190.0544 | Z48: Peak theoretical figures, not measured. See 'Assumptions & Sources' tab for constants, formulas, and citations.
A49: Database | B49: SQL Database | C49: MySQL / relational | D49: Good | E49: 6740E* | F49: 96 | G49: 250 | H49: 2.4G | I49: 3.2G | K49: E-core SKU | L49: Up to 1.32x higher MySQL performance with Intel Xeon 6787P vs. Intel Xeon 8592+ | M49: High memory capacity recommended for best performance; Target lower TDP, for ideal TCO result; Intel Xeon 6 with E-cores preferred if highest performance per watt is required vs. highest performance; Ideal recommendation of lower core count SKUs with good frequency | N49: E-core (Sierra Forest) | O49: Xeon 6700-series E-core (Birch Stream SP), 8-ch | P49: 8 | Q49: 2.4 | R49: 6400 | S49: N/A | T49: =P49*R49*Assumptions!$B$10/1000 -> 409.6 | U49: =IF(ISNUMBER(S49),P49*S49*Assumptions!$B$10/1000,"N/A") -> N/A | V49: =F49*Q49*IF(N49="E-core (Sierra Forest)",Assumptions!$B$8,Assumptions!$B$4)/1000 -> 3.6864 | W49: =F49*Q49*IF(N49="E-core (Sierra Forest)",Assumptions!$B$9,Assumptions!$B$5)/1000 -> 7.3728 | X49: =IF(N49="E-core (Sierra Forest)","N/A (no AMX)",F49*Q49*Assumptions!$B$6/1000) -> N/A (no AMX) | Y49: =IF(N49="E-core (Sierra Forest)","N/A (no AMX)",F49*Q49*Assumptions!$B$7/1000) -> N/A (no AMX) | Z49: Peak theoretical figures, not measured. See 'Assumptions & Sources' tab for constants, formulas, and citations.
A50: Database | B50: SQL Database | C50: MySQL / relational | D50: Better | E50: 6952P | F50: 96 | G50: 400 | H50: 2.1G | I50: 3.2G | J50: 3.9G | L50: Up to 1.32x higher MySQL performance with Intel Xeon 6787P vs. Intel Xeon 8592+ | M50: High memory capacity recommended for best performance; Target lower TDP, for ideal TCO result; Intel Xeon 6 with E-cores preferred if highest performance per watt is required vs. highest performance; Ideal recommendation of lower core count SKUs with good frequency | N50: P-core (Granite Rapids) | O50: Xeon 6900-series (Birch Stream AP), 12-ch | P50: 12 | Q50: 2.1 | R50: 6400 | S50: 8800 | T50: =P50*R50*Assumptions!$B$10/1000 -> 614.4 | U50: =IF(ISNUMBER(S50),P50*S50*Assumptions!$B$10/1000,"N/A") -> 844.8 | V50: =F50*Q50*IF(N50="E-core (Sierra Forest)",Assumptions!$B$8,Assumptions!$B$4)/1000 -> 6.4512 | W50: =F50*Q50*IF(N50="E-core (Sierra Forest)",Assumptions!$B$9,Assumptions!$B$5)/1000 -> 12.9024 | X50: =IF(N50="E-core (Sierra Forest)","N/A (no AMX)",F50*Q50*Assumptions!$B$6/1000) -> 206.4384 | Y50: =IF(N50="E-core (Sierra Forest)","N/A (no AMX)",F50*Q50*Assumptions!$B$7/1000) -> 412.8768 | Z50: Peak theoretical figures, not measured. See 'Assumptions & Sources' tab for constants, formulas, and citations.
A51: Database | B51: SQL Database | C51: MySQL / relational | D51: Better | E51: 6760P | F51: 64 | G51: 330 | H51: 2.2G | I51: 3.4G | J51: 3.9G | L51: Up to 1.32x higher MySQL performance with Intel Xeon 6787P vs. Intel Xeon 8592+ | M51: High memory capacity recommended for best performance; Target lower TDP, for ideal TCO result; Intel Xeon 6 with E-cores preferred if highest performance per watt is required vs. highest performance; Ideal recommendation of lower core count SKUs with good frequency | N51: P-core (Granite Rapids) | O51: Xeon 6700/6500-series (Birch Stream SP), 8-ch | P51: 8 | Q51: 2.2 | R51: 6400 | S51: 8000 | T51: =P51*R51*Assumptions!$B$10/1000 -> 409.6 | U51: =IF(ISNUMBER(S51),P51*S51*Assumptions!$B$10/1000,"N/A") -> 512 | V51: =F51*Q51*IF(N51="E-core (Sierra Forest)",Assumptions!$B$8,Assumptions!$B$4)/1000 -> 4.5056 | W51: =F51*Q51*IF(N51="E-core (Sierra Forest)",Assumptions!$B$9,Assumptions!$B$5)/1000 -> 9.0112 | X51: =IF(N51="E-core (Sierra Forest)","N/A (no AMX)",F51*Q51*Assumptions!$B$6/1000) -> 144.1792 | Y51: =IF(N51="E-core (Sierra Forest)","N/A (no AMX)",F51*Q51*Assumptions!$B$7/1000) -> 288.3584 | Z51: Peak theoretical figures, not measured. See 'Assumptions & Sources' tab for constants, formulas, and citations.
A52: Database | B52: SQL Database | C52: MySQL / relational | D52: Better | E52: 6756E* | F52: 128 | G52: 225 | H52: 1.8G | I52: 2.6G | K52: E-core SKU | L52: Up to 1.32x higher MySQL performance with Intel Xeon 6787P vs. Intel Xeon 8592+ | M52: High memory capacity recommended for best performance; Target lower TDP, for ideal TCO result; Intel Xeon 6 with E-cores preferred if highest performance per watt is required vs. highest performance; Ideal recommendation of lower core count SKUs with good frequency | N52: E-core (Sierra Forest) | O52: Xeon 6700-series E-core (Birch Stream SP), 8-ch | P52: 8 | Q52: 1.8 | R52: 6400 | S52: N/A | T52: =P52*R52*Assumptions!$B$10/1000 -> 409.6 | U52: =IF(ISNUMBER(S52),P52*S52*Assumptions!$B$10/1000,"N/A") -> N/A | V52: =F52*Q52*IF(N52="E-core (Sierra Forest)",Assumptions!$B$8,Assumptions!$B$4)/1000 -> 3.6864 | W52: =F52*Q52*IF(N52="E-core (Sierra Forest)",Assumptions!$B$9,Assumptions!$B$5)/1000 -> 7.3728 | X52: =IF(N52="E-core (Sierra Forest)","N/A (no AMX)",F52*Q52*Assumptions!$B$6/1000) -> N/A (no AMX) | Y52: =IF(N52="E-core (Sierra Forest)","N/A (no AMX)",F52*Q52*Assumptions!$B$7/1000) -> N/A (no AMX) | Z52: Peak theoretical figures, not measured. See 'Assumptions & Sources' tab for constants, formulas, and citations.
A53: Database | B53: SQL Database | C53: MySQL / relational | D53: Best | E53: 6980P | F53: 128 | G53: 500 | H53: 2G | I53: 3.2G | J53: 3.9G | L53: Up to 1.32x higher MySQL performance with Intel Xeon 6787P vs. Intel Xeon 8592+ | M53: High memory capacity recommended for best performance; Target lower TDP, for ideal TCO result; Intel Xeon 6 with E-cores preferred if highest performance per watt is required vs. highest performance; Ideal recommendation of lower core count SKUs with good frequency | N53: P-core (Granite Rapids) | O53: Xeon 6900-series (Birch Stream AP), 12-ch | P53: 12 | Q53: 2 | R53: 6400 | S53: 8800 | T53: =P53*R53*Assumptions!$B$10/1000 -> 614.4 | U53: =IF(ISNUMBER(S53),P53*S53*Assumptions!$B$10/1000,"N/A") -> 844.8 | V53: =F53*Q53*IF(N53="E-core (Sierra Forest)",Assumptions!$B$8,Assumptions!$B$4)/1000 -> 8.192 | W53: =F53*Q53*IF(N53="E-core (Sierra Forest)",Assumptions!$B$9,Assumptions!$B$5)/1000 -> 16.384 | X53: =IF(N53="E-core (Sierra Forest)","N/A (no AMX)",F53*Q53*Assumptions!$B$6/1000) -> 262.144 | Y53: =IF(N53="E-core (Sierra Forest)","N/A (no AMX)",F53*Q53*Assumptions!$B$7/1000) -> 524.288 | Z53: Peak theoretical figures, not measured. See 'Assumptions & Sources' tab for constants, formulas, and citations.
A54: Database | B54: SQL Database | C54: MySQL / relational | D54: Best | E54: 6787P | F54: 86 | G54: 350 | H54: 2G | I54: 3.2G | J54: 3.8G | L54: Up to 1.32x higher MySQL performance with Intel Xeon 6787P vs. Intel Xeon 8592+ | M54: High memory capacity recommended for best performance; Target lower TDP, for ideal TCO result; Intel Xeon 6 with E-cores preferred if highest performance per watt is required vs. highest performance; Ideal recommendation of lower core count SKUs with good frequency | N54: P-core (Granite Rapids) | O54: Xeon 6700/6500-series (Birch Stream SP), 8-ch | P54: 8 | Q54: 2 | R54: 6400 | S54: 8000 | T54: =P54*R54*Assumptions!$B$10/1000 -> 409.6 | U54: =IF(ISNUMBER(S54),P54*S54*Assumptions!$B$10/1000,"N/A") -> 512 | V54: =F54*Q54*IF(N54="E-core (Sierra Forest)",Assumptions!$B$8,Assumptions!$B$4)/1000 -> 5.504 | W54: =F54*Q54*IF(N54="E-core (Sierra Forest)",Assumptions!$B$9,Assumptions!$B$5)/1000 -> 11.008 | X54: =IF(N54="E-core (Sierra Forest)","N/A (no AMX)",F54*Q54*Assumptions!$B$6/1000) -> 176.128 | Y54: =IF(N54="E-core (Sierra Forest)","N/A (no AMX)",F54*Q54*Assumptions!$B$7/1000) -> 352.256 | Z54: Peak theoretical figures, not measured. See 'Assumptions & Sources' tab for constants, formulas, and citations.
A55: Database | B55: SQL Database | C55: MySQL / relational | D55: Best | E55: 6766E* | F55: 144 | G55: 250 | H55: 1.9G | I55: 2.7G | K55: E-core SKU | L55: Up to 1.32x higher MySQL performance with Intel Xeon 6787P vs. Intel Xeon 8592+ | M55: High memory capacity recommended for best performance; Target lower TDP, for ideal TCO result; Intel Xeon 6 with E-cores preferred if highest performance per watt is required vs. highest performance; Ideal recommendation of lower core count SKUs with good frequency | N55: E-core (Sierra Forest) | O55: Xeon 6700-series E-core (Birch Stream SP), 8-ch | P55: 8 | Q55: 1.9 | R55: 6400 | S55: N/A | T55: =P55*R55*Assumptions!$B$10/1000 -> 409.6 | U55: =IF(ISNUMBER(S55),P55*S55*Assumptions!$B$10/1000,"N/A") -> N/A | V55: =F55*Q55*IF(N55="E-core (Sierra Forest)",Assumptions!$B$8,Assumptions!$B$4)/1000 -> 4.3776 | W55: =F55*Q55*IF(N55="E-core (Sierra Forest)",Assumptions!$B$9,Assumptions!$B$5)/1000 -> 8.7552 | X55: =IF(N55="E-core (Sierra Forest)","N/A (no AMX)",F55*Q55*Assumptions!$B$6/1000) -> N/A (no AMX) | Y55: =IF(N55="E-core (Sierra Forest)","N/A (no AMX)",F55*Q55*Assumptions!$B$7/1000) -> N/A (no AMX) | Z55: Peak theoretical figures, not measured. See 'Assumptions & Sources' tab for constants, formulas, and citations.
A56: Database | B56: NoSQL Database | C56: MongoDB, Cassandra | D56: Good | E56: 6747P | F56: 48 | G56: 330 | H56: 2.7G | I56: 3.8G | J56: 3.9G | L56: Up to 2.05x higher MongoDB performance and 1.43x perf/watt with the new Intel Xeon 6980P (DDR5) vs. Intel Xeon 8592; Up to 1.17x higher MongoDB performance with Intel Xeon 6980P vs. AMD EPYC 9755 | M56: Target lower TDP, for ideal TCO result; Intel Xeon 6 with E-cores preferred if highest performance per watt is required vs. highest performance | N56: P-core (Granite Rapids) | O56: Xeon 6700/6500-series (Birch Stream SP), 8-ch | P56: 8 | Q56: 2.7 | R56: 6400 | S56: 8000 | T56: =P56*R56*Assumptions!$B$10/1000 -> 409.6 | U56: =IF(ISNUMBER(S56),P56*S56*Assumptions!$B$10/1000,"N/A") -> 512 | V56: =F56*Q56*IF(N56="E-core (Sierra Forest)",Assumptions!$B$8,Assumptions!$B$4)/1000 -> 4.1472 | W56: =F56*Q56*IF(N56="E-core (Sierra Forest)",Assumptions!$B$9,Assumptions!$B$5)/1000 -> 8.2944 | X56: =IF(N56="E-core (Sierra Forest)","N/A (no AMX)",F56*Q56*Assumptions!$B$6/1000) -> 132.7104 | Y56: =IF(N56="E-core (Sierra Forest)","N/A (no AMX)",F56*Q56*Assumptions!$B$7/1000) -> 265.4208 | Z56: Peak theoretical figures, not measured. See 'Assumptions & Sources' tab for constants, formulas, and citations.
A57: Database | B57: NoSQL Database | C57: MongoDB, Cassandra | D57: Good | E57: 6737P | F57: 32 | G57: 270 | H57: 2.9G | I57: 4G | J57: 4G | L57: Up to 2.05x higher MongoDB performance and 1.43x perf/watt with the new Intel Xeon 6980P (DDR5) vs. Intel Xeon 8592; Up to 1.17x higher MongoDB performance with Intel Xeon 6980P vs. AMD EPYC 9755 | M57: Target lower TDP, for ideal TCO result; Intel Xeon 6 with E-cores preferred if highest performance per watt is required vs. highest performance | N57: P-core (Granite Rapids) | O57: Xeon 6700/6500-series (Birch Stream SP), 8-ch | P57: 8 | Q57: 2.9 | R57: 6400 | S57: 8000 | T57: =P57*R57*Assumptions!$B$10/1000 -> 409.6 | U57: =IF(ISNUMBER(S57),P57*S57*Assumptions!$B$10/1000,"N/A") -> 512 | V57: =F57*Q57*IF(N57="E-core (Sierra Forest)",Assumptions!$B$8,Assumptions!$B$4)/1000 -> 2.9696 | W57: =F57*Q57*IF(N57="E-core (Sierra Forest)",Assumptions!$B$9,Assumptions!$B$5)/1000 -> 5.9392 | X57: =IF(N57="E-core (Sierra Forest)","N/A (no AMX)",F57*Q57*Assumptions!$B$6/1000) -> 95.0272 | Y57: =IF(N57="E-core (Sierra Forest)","N/A (no AMX)",F57*Q57*Assumptions!$B$7/1000) -> 190.0544 | Z57: Peak theoretical figures, not measured. See 'Assumptions & Sources' tab for constants, formulas, and citations.
A58: Database | B58: NoSQL Database | C58: MongoDB, Cassandra | D58: Good | E58: 6740E* | F58: 96 | G58: 250 | H58: 2.4G | I58: 3.2G | K58: E-core SKU | L58: Up to 2.05x higher MongoDB performance and 1.43x perf/watt with the new Intel Xeon 6980P (DDR5) vs. Intel Xeon 8592; Up to 1.17x higher MongoDB performance with Intel Xeon 6980P vs. AMD EPYC 9755 | M58: Target lower TDP, for ideal TCO result; Intel Xeon 6 with E-cores preferred if highest performance per watt is required vs. highest performance | N58: E-core (Sierra Forest) | O58: Xeon 6700-series E-core (Birch Stream SP), 8-ch | P58: 8 | Q58: 2.4 | R58: 6400 | S58: N/A | T58: =P58*R58*Assumptions!$B$10/1000 -> 409.6 | U58: =IF(ISNUMBER(S58),P58*S58*Assumptions!$B$10/1000,"N/A") -> N/A | V58: =F58*Q58*IF(N58="E-core (Sierra Forest)",Assumptions!$B$8,Assumptions!$B$4)/1000 -> 3.6864 | W58: =F58*Q58*IF(N58="E-core (Sierra Forest)",Assumptions!$B$9,Assumptions!$B$5)/1000 -> 7.3728 | X58: =IF(N58="E-core (Sierra Forest)","N/A (no AMX)",F58*Q58*Assumptions!$B$6/1000) -> N/A (no AMX) | Y58: =IF(N58="E-core (Sierra Forest)","N/A (no AMX)",F58*Q58*Assumptions!$B$7/1000) -> N/A (no AMX) | Z58: Peak theoretical figures, not measured. See 'Assumptions & Sources' tab for constants, formulas, and citations.
...

Sheet Assumptions
A1: Assumptions & Sources – TFLOPS and Memory Bandwidth Estimates
A3: Constant | B3: Value | C3: Notes
A4: AVX-512 FP64 FLOPs/cycle/core – P-core (2× 512-bit FMA) | B4: 32 | C4: 8 doubles/vector × 2 FMA units × 2 ops (mul+add) = 32
A5: AVX-512 FP32 FLOPs/cycle/core – P-core (2× 512-bit FMA) | B5: 64 | C5: 16 floats/vector × 2 FMA units × 2 ops = 64 (2× the FP64 rate)
A6: AMX BF16/FP16 FLOPs/cycle/core | B6: 1024 | C6: Intel-published figure, Xeon 6 Product Brief
A7: AMX INT8 OPs/cycle/core | B7: 2048 | C7: Intel-published figure, Xeon 6 Product Brief
A8: AVX-512 FP64 FLOPs/cycle/core – E-core (Sierra Forest, est.) | B8: 16 | C8: Estimate: Sierra Forest E-cores implement a narrower/single-FMA-equivalent AVX-512 datapath and have no AMX. Treat as approximate; not an Intel-published figure.
A9: AVX-512 FP32 FLOPs/cycle/core – E-core (est.) | B9: 32 | C9: 2× the E-core FP64 estimate, same caveat as above
A10: Bytes per transfer per DDR5 channel | B10: 8 | C10: DDR5 channel is 64-bit wide = 8 bytes/transfer
A11: DDR5 RDIMM speed – Xeon 6 (MT/s) | B11: 6400 | C11: Intel Xeon 6 Product Brief; Kingston Birch Stream platform guide
A12: DDR5 MRDIMM speed – Xeon 6900-series / AP platform (MT/s) | B12: 8800 | C12: Kingston Birch Stream guide; Intel Xeon 6 Product Brief (2nd Gen MRDIMM)
A13: DDR5 MRDIMM speed – Xeon 6700/6500-series / SP platform (MT/s) | B13: 8000 | C13: Kingston Birch Stream guide
A14: DDR5 RDIMM speed – Legacy 5th Gen Xeon Scalable / Emerald Rapids (MT/s) | B14: 5600 | C14: Intel 5th Gen Xeon Scalable spec (pre-Xeon 6 platform); MRDIMM support for these specific SKUs not verified, so left as N/A
A16: Formulas used in the 'SKU Recommendations' tab
A17: Peak Mem BW – RDIMM (GB/s) | B17: Channels × RDIMM speed (MT/s) × 8 bytes / 1000
A18: Peak Mem BW – MRDIMM (GB/s) | B18: Channels × MRDIMM speed (MT/s) × 8 bytes / 1000 (N/A where MRDIMM isn't qualified)
A19: AVX-512 FP64 TFLOPS (peak) | B19: Cores × Base Clock (GHz) × FP64 FLOPs/cycle/core ÷ 1000
A20: AVX-512 FP32 TFLOPS (peak) | B20: Cores × Base Clock (GHz) × FP32 FLOPs/cycle/core ÷ 1000
A21: AMX BF16/FP16 TFLOPS (peak) | B21: Cores × Base Clock (GHz) × 1024 ÷ 1000 (P-core / legacy only, N/A for E-core)
A22: AMX INT8 TOPS (peak) | B22: Cores × Base Clock (GHz) × 2048 ÷ 1000 (P-core / legacy only, N/A for E-core)
A24: Methodology notes
A25: • All TFLOPS figures are THEORETICAL PEAK compute, calculated at each SKU's BASE clock (not turbo), which is the standard, conservative convention used in HPC peak-FLOPS estimates (e.g. HPL/LINPACK peak calculations) because heavy AVX-512/AMX code typically runs at or near base clock rather than single-core turbo.
A26: • Real, sustained performance will be lower than peak — typically 60–90% of peak for well-optimized HPC/AI kernels, and considerably lower for general-purpose or memory-bound code. Use these figures for relative SKU comparison, not capacity planning.
A27: • Memory bandwidth figures are theoretical peak transfer rate of the memory subsystem (channels × speed × width) and do not account for real-world DDR5 efficiency losses (typically 70–85% of peak is achievable in practice, e.g. STREAM benchmark).
A28: • Xeon 6 SKU platform/channel assignment is based on the SKU numbering convention: 6900-series (e.g. 6980P, 6972P, 6960P, 6952P, 6944P, 6978P, 6962P) = 12-channel 'AP' platform (Birch Stream); 6700/6500-series (all other '...P' SKUs) = 8-channel 'SP' platform. 'E' suffix SKUs (6740E, 6756E, 6766E) are Sierra Forest E-core parts on the 8-channel SP platform. 6558Q and 8562Y+ are 5th Gen Xeon Scalable (Emerald Rapids) SKUs, not Xeon 6, included in the original HFT slide as an alternative low-latency option.
A29: • AMX (BF16/FP16 = 1024 FLOPs/cycle/core, INT8 = 2048 OPs/cycle/core) is Intel's own published per-core peak figure from the Xeon 6 Product Brief; it is not present on E-core (Sierra Forest) SKUs, so those cells return 'N/A (no AMX)'.
A31: Sources
A32: • Intel Xeon 6 Product Brief (AMX FLOPs/cycle, DDR5-6400 / MRDIMM support)
A33: https://www.intel.com/content/www/us/en/products/docs/xeon-6-product-brief.html
A34: • Kingston – Intel Xeon 6 Processor Platform (Birch Stream) DDR5 channel/speed by series
A35: https://www.kingston.com/en/memory/server-memory/birch-stream
A36: • Kingston – Intel Xeon 6 Guide: Key Features, Benefits & Use Cases
... A45: https://wccftech.com/intel-xeon-6-leaps-to-8000-mt-s-memory-now-but-the-real-payoff-waits-for-8800-mt-s-mrdimm-in-2027/
