Workbook

Sheet Cards
A1: Accelerator reference (usable = capacity x 90%)
A2: Accelerator | B2: HBM/VRAM (GiB) | C2: Util cap | D2: Usable (GiB) | E2: Notes
A3: Intel Arc Pro B60 24GB | B3: 24 | C3: 0.9 | D3: =B3*C3 -> 21.6 | E3: Edge/workstation; TP for larger models
A4: NVIDIA L40S 48GB | B4: 48 | C4: 0.9 | D4: =B4*C4 -> 43.2 | E4: PCIe datacenter
A5: NVIDIA H100 SXM 80GB | B5: 80 | C5: 0.9 | D5: =B5*C5 -> 72 | E5: Datacenter standard
A6: Intel Gaudi 3 128GB | B6: 128 | C6: 0.9 | D6: =B6*C6 -> 115.2 | E6: vLLM-fork; large single-card KV budget
A7: NVIDIA H200 141GB | B7: 141 | C7: 0.9 | D7: =B7*C7 -> 126.9 | E7: Large single-card home
A8: NVIDIA B200 180GB | B8: 180 | C8: 0.9 | D8: =B8*C8 -> 162 | E8: Blackwell
A9: AMD MI300X 192GB | B9: 192 | C9: 0.9 | D9: =B9*C9 -> 172.8 | E9: Largest single-card capacity
A11: Sorted ascending by capacity so the smallest-fit lookup on the sizing sheet works. Add cards in ascending order and extend ranges $A$3:$A$9 / $D$3:$D$9 if you add rows.

Sheet Method & Legend
A1: Method, formula & legend
A3: The vLLM load-time KV formula
A4: At init, vLLM computes bytes per token per layer = 2 x num_kv_heads x head_dim x dtype_bytes. The 2 is K and V.
A5: It then multiplies by cached token-layers and by concurrent sequences, and allocates that as paged blocks
A6: (default block_size = 16 tokens). Total KV = 2 x n_kv_heads x head_dim x bytes x layers x seq_len x num_seqs.
A7: This workbook mirrors that: bytes/tok/layer (col L) x cached token-layers/seq (col M) x concurrency x (1+overhead).
A9: KV cache TYPE - why most catalog models show zero
A10: Decoder : autoregressive decoder-only transformer. Full KV cache over the whole context. Formula applies directly.
A11: Hybrid : decoder with sliding-window (banded) + global layers (GPT-OSS, Gemma 3/4) OR conv+attention (LFM2). Dense
A12: layers cache the full sequence; window layers cache only min(seq, window). This is the big KV saver at long context.
A13: Enc-Dec : encoder-decoder (Whisper, IndicTrans2, GLM-OCR). The encoder is single-pass (no KV cache); the decoder caches
A14: only its own generated tokens (output length), plus fixed cross-attention to encoder states. KV is small.
... A41: Orpheus TTS sequence is audio-codec tokens, not text; the 4K/1K text assumption is a rough proxy.

Sheet Offload Refs
A1: Offload analysis - reference data
A2: Yellow cells are editable. Provenance: G=verified/well-established, Y=estimate or unpublished (verify before external).
A4: MODEL PARAMETERS (for prefill FLOPs + KV size)
A5: Model | B5: Active params (B) | C5: Layers | D5: Dense/self-attn L | E5: Window L | F5: Window | G5: Q heads | H5: KV heads | I5: Head dim | J5: Prov | K5: Note
A6: Gemma 4 26B-A4B-IT | B6: 3.8 | C6: 30 | D6: 4 | E6: 26 | F6: 4096 | G6: 8 | H6: 4 | I6: 256 | J6: Y | K6: MoE 3.8B active. Global layers hd512 (approx as 256). Verify
A7: Gemma-3-4B-it | B7: 4 | C7: 34 | D7: 6 | E7: 28 | F7: 1024 | G7: 8 | H7: 4 | I7: 256 | J7: G | K7: Dense. 5:1 local:global, window 1024
A8: Gemma-4-E4B-it | B8: 4 | C8: 34 | D8: 6 | E8: 28 | F8: 1024 | G8: 8 | H8: 4 | I8: 256 | J8: Y | K8: Elastic 4B; arch assumed Gemma-3-4B-like
A9: GPT-OSS-120B | B9: 5.1 | C9: 36 | D9: 18 | E9: 18 | F9: 128 | G9: 64 | H9: 8 | I9: 64 | J9: G | K9: MoE 5.1B active. 18 dense/18 banded(128). Model card 2508.10925
A10: LFM2.5-1.2B-Instruct | B10: 1.2 | C10: 6 | D10: 6 | E10: 0 | F10: 0 | G10: 16 | H10: 8 | I10: 128 | J10: Y | K10: Liquid hybrid: only ~6 attention layers; conv blocks add compute NOT captured by 2PT. Rough
A11: Llama 3.3 70B Instruct | B11: 70 | C11: 80 | D11: 80 | E11: 0 | F11: 0 | G11: 64 | H11: 8 | I11: 128 | J11: G | K11: Dense 70B
A12: Llama-3.2-1B-it | B12: 1.24 | C12: 16 | D12: 16 | E12: 0 | F12: 0 | G12: 32 | H12: 8 | I12: 64 | J12: G | K12: Dense 1.24B
A13: Llama-3.2-8B-it | B13: 8 | C13: 32 | D13: 32 | E13: 0 | F13: 0 | G13: 32 | H13: 8 | I13: 128 | J13: Y | K13: No real Meta 3.2-8B; treated as Llama 3.1 8B
A14: Qwen3-30B-A3B | B14: 3.3 | C14: 48 | D14: 48 | E14: 0 | F14: 0 | G14: 32 | H14: 4 | I14: 128 | J14: G | K14: MoE 3.3B active (HF verified)
A15: Qwen3.5-4B | B15: 4 | C15: 36 | D15: 36 | E15: 0 | F15: 0 | G15: 32 | H15: 8 | I15: 128 | J15: Y | K15: 2026-dated; Qwen3-4B arch assumed
A16: Qwen3.6-27B | B16: 27 | C16: 64 | D16: 64 | E16: 0 | F16: 0 | G16: 40 | H16: 8 | I16: 128 | J16: Y | K16: 2026-dated dense; Q-heads/layers estimated
A17: Sarvam-105B | B17: 10 | C17: 80 | D17: 80 | E17: 0 | F17: 0 | G17: 40 | H17: 8 | I17: 128 | J17: Y | K17: MoE; ACTIVE PARAMS UNKNOWN - placeholder 10B. Do not assert
A18: Sarvam-30B | B18: 2.4 | C18: 48 | D18: 48 | E18: 0 | F18: 0 | G18: 32 | H18: 4 | I18: 128 | J18: Y | K18: MoE ~2.4B active; arch placeholder
A20: STORAGE / MEMORY MEDIA - bandwidth (GB/s, decimal)
A21: Medium | B21: Read BW (GB/s) | C21: Prov | D21: Basis / note
A22: DRAM (host DDR5-6400, 12ch/socket) | B22: 600 | C22: G | D22: ~614 GB/s per socket; MRDIMM-8800 ~845. Per-socket aggregate
A23: CXL Flat Memory Mode (Gen5 x16 expander) | B23: 50 | C23: Y | D23: ~50 GB/s per module (Gen5 x16 ~64 theoretical). Flat mode HW-interleaves DRAM+CXL; scales with modules
A24: NVMe (PCIe Gen5 x4 SSD, seq read) | B24: 14 | C24: G | D24: ~14 GB/s/drive Gen5 (Gen4 ~7). RAID/multiple drives scale linearly
A25: All-Flash array (NVMe-oF over fabric) | B25: 40 | C25: Y | D25: NIC-bound: dual 200GbE ~40-50 GB/s; 800GbE ~100. Aggregate array BW higher, per-client capped
A26: Write -> GPU memory (PCIe Gen5 x16) | B26: 55 | C26: G | D26: ~55 GB/s effective (Gen5 x16 ~64 theo). B70 & CRI are PCIe cards. Same write cost for every medium
A28: ACCELERATOR - peak BF16 matrix TFLOPS
A29: Accelerator | B29: Peak BF16 TFLOPS | C29: Prov | D29: Basis / note
A30: Intel Arc Pro B70 | B30: 183.5 | C30: Y | D30: XMX BF16 = INT8 peak (367 TOPS) / 2. NB: vector FP16 (~45.9) is a different, lower path - not used for matmul-bound prefill
A31: Intel Crescent Island (CRI) | B31: 600 | C31: Y | D31: Intel has NOT published throughput (Computex 2026). Placeholder - EDIT on disclosure. 350W Xe3P, 160-480GB LPDDR5X

Sheet Offload vs Recompute
A1: KV-Cache Offload vs Recompute - Prefill economics
A2: For a cached prefix, is it faster to LOAD the KV from off-GPU media (read + write-to-GPU) or RECOMPUTE it via prefill? Pick a model and accelerator; edit yellow levers. Single sequence (concurrency=1) - concurrency scales both sides equally.
A4: SELECTORS & LEVERS | F4: MODEL (auto)
A5: Model | C5: GPT-OSS-120B | F5: Active params (B) | H5: =INDEX('Offload Refs'!B$6:B$18,MATCH($C$5,'Offload Refs'!$A$6:$A$18,0)) -> 5.1
A6: Accelerator (drives verdict) | C6: Intel Crescent Island (CRI) | F6: Layers | H6: =INDEX('Offload Refs'!C$6:C$18,MATCH($C$5,'Offload Refs'!$A$6:$A$18,0)) -> 36
A7: KV bytes / element | C7: 2 | D7: FP16/BF16=2, FP8=1, INT4=0.5 | F7: Dense layers | H7: =INDEX('Offload Refs'!D$6:D$18,MATCH($C$5,'Offload Refs'!$A$6:$A$18,0)) -> 18
A8: Achieved efficiency (MFU) | C8: 0.6 | D8: fraction of peak actually sustained | F8: Window layers | H8: =INDEX('Offload Refs'!E$6:E$18,MATCH($C$5,'Offload Refs'!$A$6:$A$18,0)) -> 18
A9: Causal factor (attention) | C9: 0.5 | D9: 0.5 = causal mask halves QK^T/AV work | F9: Window size | H9: =INDEX('Offload Refs'!F$6:F$18,MATCH($C$5,'Offload Refs'!$A$6:$A$18,0)) -> 128
F10: Q heads | H10: =INDEX('Offload Refs'!G$6:G$18,MATCH($C$5,'Offload Refs'!$A$6:$A$18,0)) -> 64
F11: KV heads | H11: =INDEX('Offload Refs'!H$6:H$18,MATCH($C$5,'Offload Refs'!$A$6:$A$18,0)) -> 8
F12: Head dim | H12: =INDEX('Offload Refs'!I$6:I$18,MATCH($C$5,'Offload Refs'!$A$6:$A$18,0)) -> 64
F13: Q width d_q = Qheads x hd | H13: =H10*H12 -> 4096
F14: KV bytes/tok/layer | H14: =2*H11*H12*$C$7 -> 2048
F16: Sel. accel peak BF16 TFLOPS | H16: =INDEX('Offload Refs'!$B$30:$B$31,MATCH($C$6,'Offload Refs'!$A$30:$A$31,0)) -> 600
F17: Sel. accel achieved TFLOPS | H17: =H16*$C$8 -> 360
A20: A. ABSOLUTE - per prefill context length
A21: Context (tokens) | B21: KV size (GiB) | C21: Prefill (TFLOP) | D21: Recompute B70 (ms) | E21: Recompute CRI (ms) | F21: Read DRAM (ms) | G21: Read CXL (ms) | H21: Read NVMe (ms) | I21: Read Flash (ms) | J21: Write->GPU (ms)
A22: 4096 | B22: =$H$14*($H$7*A22+$H$8*MIN(A22,$H$9))/1073741824 -> 0.14501953 | C22: =(2*$H$5*1000000000*A22+4*$C$9*$H$13*($H$7*A22^2+$H$8*A22*MIN(A22,$H$9)))/1000000000000 -> 44.330411 | D22: =(2*$H$5*1000000000*A22+4*$C$9*$H$13*($H$7*A22^2+$H$8*A22*MIN(A22,$H$9)))/('Offload Refs'!$B$30*$C$8*1000000000000)*1000 -> 402.6377 | E22: =(2*$H$5*1000000000*A22+4*$C$9*$H$13*($H$7*A22^2+$H$8*A22*MIN(A22,$H$9)))/('Offload Refs'!$B$31*$C$8*1000000000000)*1000 -> 123.14003 | F22: =$H$14*($H$7*A22+$H$8*MIN(A22,$H$9))/('Offload Refs'!$B$22*1000000000)*1000 -> 0.25952256 | G22: =$H$14*($H$7*A22+$H$8*MIN(A22,$H$9))/('Offload Refs'!$B$23*1000000000)*1000 -> 3.1142707 | H22: =$H$14*($H$7*A22+$H$8*MIN(A22,$H$9))/('Offload Refs'!$B$24*1000000000)*1000 -> 11.122395 | I22: =$H$14*($H$7*A22+$H$8*MIN(A22,$H$9))/('Offload Refs'!$B$25*1000000000)*1000 -> 3.8928384 | J22: =$H$14*($H$7*A22+$H$8*MIN(A22,$H$9))/('Offload Refs'!$B$26*1000000000)*1000 -> 2.8311552
A23: 8192 | B23: =$H$14*($H$7*A23+$H$8*MIN(A23,$H$9))/1073741824 -> 0.28564453 | C23: =(2*$H$5*1000000000*A23+4*$C$9*$H$13*($H$7*A23^2+$H$8*A23*MIN(A23,$H$9)))/1000000000000 -> 93.608623 | D23: =(2*$H$5*1000000000*A23+4*$C$9*$H$13*($H$7*A23^2+$H$8*A23*MIN(A23,$H$9)))/('Offload Refs'!$B$30*$C$8*1000000000000)*1000 -> 850.21456 | E23: =(2*$H$5*1000000000*A23+4*$C$9*$H$13*($H$7*A23^2+$H$8*A23*MIN(A23,$H$9)))/('Offload Refs'!$B$31*$C$8*1000000000000)*1000 -> 260.02395 | F23: =$H$14*($H$7*A23+$H$8*MIN(A23,$H$9))/('Offload Refs'!$B$22*1000000000)*1000 -> 0.5111808 | G23: =$H$14*($H$7*A23+$H$8*MIN(A23,$H$9))/('Offload Refs'!$B$23*1000000000)*1000 -> 6.1341696 | H23: =$H$14*($H$7*A23+$H$8*MIN(A23,$H$9))/('Offload Refs'!$B$24*1000000000)*1000 -> 21.907749 | I23: =$H$14*($H$7*A23+$H$8*MIN(A23,$H$9))/('Offload Refs'!$B$25*1000000000)*1000 -> 7.667712 | J23: =$H$14*($H$7*A23+$H$8*MIN(A23,$H$9))/('Offload Refs'!$B$26*1000000000)*1000 -> 5.5765178
A24: 16384 | B24: =$H$14*($H$7*A24+$H$8*MIN(A24,$H$9))/1073741824 -> 0.56689453 | C24: =(2*$H$5*1000000000*A24+4*$C$9*$H$13*($H$7*A24^2+$H$8*A24*MIN(A24,$H$9)))/1000000000000 -> 207.00846 | D24: =(2*$H$5*1000000000*A24+4*$C$9*$H$13*($H$7*A24^2+$H$8*A24*MIN(A24,$H$9)))/('Offload Refs'!$B$30*$C$8*1000000000000)*1000 -> 1880.1858 | E24: =(2*$H$5*1000000000*A24+4*$C$9*$H$13*($H$7*A24^2+$H$8*A24*MIN(A24,$H$9)))/('Offload Refs'!$B$31*$C$8*1000000000000)*1000 -> 575.02349 | F24: =$H$14*($H$7*A24+$H$8*MIN(A24,$H$9))/('Offload Refs'!$B$22*1000000000)*1000 -> 1.0144973 | G24: =$H$14*($H$7*A24+$H$8*MIN(A24,$H$9))/('Offload Refs'!$B$23*1000000000)*1000 -> 12.173967 | H24: =$H$14*($H$7*A24+$H$8*MIN(A24,$H$9))/('Offload Refs'!$B$24*1000000000)*1000 -> 43.478455 | I24: =$H$14*($H$7*A24+$H$8*MIN(A24,$H$9))/('Offload Refs'!$B$25*1000000000)*1000 -> 15.217459 | J24: =$H$14*($H$7*A24+$H$8*MIN(A24,$H$9))/('Offload Refs'!$B$26*1000000000)*1000 -> 11.067243
A25: 32768 | B25: =$H$14*($H$7*A25+$H$8*MIN(A25,$H$9))/1073741824 -> 1.1293945 | C25: =(2*$H$5*1000000000*A25+4*$C$9*$H$13*($H$7*A25^2+$H$8*A25*MIN(A25,$H$9)))/1000000000000 -> 493.18175 | D25: =(2*$H$5*1000000000*A25+4*$C$9*$H$13*($H$7*A25^2+$H$8*A25*MIN(A25,$H$9)))/('Offload Refs'!$B$30*$C$8*1000000000000)*1000 -> 4479.3983 | E25: =(2*$H$5*1000000000*A25+4*$C$9*$H$13*($H$7*A25^2+$H$8*A25*MIN(A25,$H$9)))/('Offload Refs'!$B$31*$C$8*1000000000000)*1000 -> 1369.9493 | F25: =$H$14*($H$7*A25+$H$8*MIN(A25,$H$9))/('Offload Refs'!$B$22*1000000000)*1000 -> 2.0211302 | G25: =$H$14*($H$7*A25+$H$8*MIN(A25,$H$9))/('Offload Refs'!$B$23*1000000000)*1000 -> 24.253563 | H25: =$H$14*($H$7*A25+$H$8*MIN(A25,$H$9))/('Offload Refs'!$B$24*1000000000)*1000 -> 86.619867 | I25: =$H$14*($H$7*A25+$H$8*MIN(A25,$H$9))/('Offload Refs'!$B$25*1000000000)*1000 -> 30.316954 | J25: =$H$14*($H$7*A25+$H$8*MIN(A25,$H$9))/('Offload Refs'!$B$26*1000000000)*1000 -> 22.048694
A26: Total load per medium = its Read column + Write->GPU (serial). Pipelined read/write overlaps -> take max() of the two instead.
A28: B. VERDICT - total load (read+write) vs recompute on SELECTED accelerator
A29: Context | B29: Recompute (ms) | C29: DRAM load (ms) | D29: CXL load (ms) | E29: NVMe load (ms) | F29: Flash load (ms) | G29: Fastest offload (ms) | H29: Offload vs recompute
A30: =A22 -> 4096 | B30: =(2*$H$5*1000000000*A22+4*$C$9*$H$13*($H$7*A22^2+$H$8*A22*MIN(A22,$H$9)))/($H$17*1000000000000)*1000 -> 123.14003 | C30: =F22+$J22 -> 3.0906778 | D30: =G22+$J22 -> 5.9454259 | E30: =H22+$J22 -> 13.953551 | F30: =I22+$J22 -> 6.7239936 | G30: =MIN(C30:F30) -> 3.0906778 | H30: =IF(G30<B30,"OFFLOAD wins ("&TEXT(B30/G30,"0.0")&"x)","RECOMPUTE wins ("&TEXT(G30/B30,"0.0")&"x)") -> OFFLOAD wins (39.8x)
A31: =A23 -> 8192 | B31: =(2*$H$5*1000000000*A23+4*$C$9*$H$13*($H$7*A23^2+$H$8*A23*MIN(A23,$H$9)))/($H$17*1000000000000)*1000 -> 260.02395 | C31: =F23+$J23 -> 6.0876986 | D31: =G23+$J23 -> 11.710687 | E31: =H23+$J23 -> 27.484266 | F31: =I23+$J23 -> 13.24423 | G31: =MIN(C31:F31) -> 6.0876986 | H31: =IF(G31<B31,"OFFLOAD wins ("&TEXT(B31/G31,"0.0")&"x)","RECOMPUTE wins ("&TEXT(G31/B31,"0.0")&"x)") -> OFFLOAD wins (42.7x)
A32: =A24 -> 16384 | B32: =(2*$H$5*1000000000*A24+4*$C$9*$H$13*($H$7*A24^2+$H$8*A24*MIN(A24,$H$9)))/($H$17*1000000000000)*1000 -> 575.02349 | C32: =F24+$J24 -> 12.08174 | D32: =G24+$J24 -> 23.24121 | E32: =H24+$J24 -> 54.545698 | F32: =I24+$J24 -> 26.284702 | G32: =MIN(C32:F32) -> 12.08174 | H32: =IF(G32<B32,"OFFLOAD wins ("&TEXT(B32/G32,"0.0")&"x)","RECOMPUTE wins ("&TEXT(G32/B32,"0.0")&"x)") -> OFFLOAD wins (47.6x)
A33: =A25 -> 32768 | B33: =(2*$H$5*1000000000*A25+4*$C$9*$H$13*($H$7*A25^2+$H$8*A25*MIN(A25,$H$9)))/($H$17*1000000000000)*1000 -> 1369.9493 | C33: =F25+$J25 -> 24.069824 | D33: =G25+$J25 -> 46.302256 | E33: =H25+$J25 -> 108.66856 | F33: =I25+$J25 -> 52.365647 | G33: =MIN(C33:F33) -> 24.069824 | H33: =IF(G33<B33,"OFFLOAD wins ("&TEXT(B33/G33,"0.0")&"x)","RECOMPUTE wins ("&TEXT(G33/B33,"0.0")&"x)") -> OFFLOAD wins (56.9x)
A36: C. INCREMENTAL vs 4K baseline (extra KV to load vs extra prefill to recompute)
A37: Delta | B37: Extra KV (GiB) | C37: Extra prefill (TFLOP) | D37: Extra recompute (ms, sel accel) | E37: +DRAM load (ms) | F37: +CXL load (ms) | G37: +NVMe load (ms) | H37: +Flash load (ms) | I37: Incremental verdict
A38: 4K -> 8K | B38: =(($H$14*($H$7*8192+$H$8*MIN(8192,$H$9)))-($H$14*($H$7*4096+$H$8*MIN(4096,$H$9))))/1073741824 -> 0.140625 | C38: =(((2*$H$5*1000000000*8192+4*$C$9*$H$13*($H$7*8192^2+$H$8*8192*MIN(8192,$H$9))))-((2*$H$5*1000000000*4096+4*$C$9*$H$13*($H$7*4096^2+$H$8*4096*MIN(4096,$H$9)))))/1000000000000 -> 49.278213 | D38: =(((2*$H$5*1000000000*8192+4*$C$9*$H$13*($H$7*8192^2+$H$8*8192*MIN(8192,$H$9))))-((2*$H$5*1000000000*4096+4*$C$9*$H$13*($H$7*4096^2+$H$8*4096*MIN(4096,$H$9)))))/($H$17*1000000000000)*1000 -> 136.88392 | E38: =(($H$14*($H$7*8192+$H$8*MIN(8192,$H$9)))-($H$14*($H$7*4096+$H$8*MIN(4096,$H$9))))/('Offload Refs'!$B$22*1000000000)*1000+(($H$14*($H$7*8192+$H$8*MIN(8192,$H$9)))-($H$14*($H$7*4096+$H$8*MIN(4096,$H$9))))/('Offload Refs'!$B$26*1000000000)*1000 -> 2.9970209 | F38: =(($H$14*($H$7*8192+$H$8*MIN(8192,$H$9)))-($H$14*($H$7*4096+$H$8*MIN(4096,$H$9))))/('Offload Refs'!$B$23*1000000000)*1000+(($H$14*($H$7*8192+$H$8*MIN(8192,$H$9)))-($H$14*($H$7*4096+$H$8*MIN(4096,$H$9))))/('Offload Refs'!$B$26*1000000000)*1000 -> 5.7652615 | G38: =(($H$14*($H$7*8192+$H$8*MIN(8192,$H$9)))-($H$14*($H$7*4096+$H$8*MIN(4096,$H$9))))/('Offload Refs'!$B$24*1000000000)*1000+(($H$14*($H$7*8192+$H$8*MIN(8192,$H$9)))-($H$14*($H$7*4096+$H$8*MIN(4096,$H$9))))/('Offload Refs'!$B$26*1000000000)*1000 -> 13.530716 | H38: =(($H$14*($H$7*8192+$H$8*MIN(8192,$H$9)))-($H$14*($H$7*4096+$H$8*MIN(4096,$H$9))))/('Offload Refs'!$B$25*1000000000)*1000+(($H$14*($H$7*8192+$H$8*MIN(8192,$H$9)))-($H$14*($H$7*4096+$H$8*MIN(4096,$H$9))))/('Offload Refs'!$B$26*1000000000)*1000 -> 6.5202362 | I38: =IF(MIN(E38:H38)<D38,"OFFLOAD delta wins","RECOMPUTE delta wins") -> OFFLOAD delta wins
A39: 4K -> 16K | B39: =(($H$14*($H$7*16384+$H$8*MIN(16384,$H$9)))-($H$14*($H$7*4096+$H$8*MIN(4096,$H$9))))/1073741824 -> 0.421875 | C39: =(((2*$H$5*1000000000*16384+4*$C$9*$H$13*($H$7*16384^2+$H$8*16384*MIN(16384,$H$9))))-((2*$H$5*1000000000*4096+4*$C$9*$H$13*($H$7*4096^2+$H$8*4096*MIN(4096,$H$9)))))/1000000000000 -> 162.67805 | D39: =(((2*$H$5*1000000000*16384+4*$C$9*$H$13*($H$7*16384^2+$H$8*16384*MIN(16384,$H$9))))-((2*$H$5*1000000000*4096+4*$C$9*$H$13*($H$7*4096^2+$H$8*4096*MIN(4096,$H$9)))))/($H$17*1000000000000)*1000 -> 451.88346 | E39: =(($H$14*($H$7*16384+$H$8*MIN(16384,$H$9)))-($H$14*($H$7*4096+$H$8*MIN(4096,$H$9))))/('Offload Refs'!$B$22*1000000000)*1000+(($H$14*($H$7*16384+$H$8*MIN(16384,$H$9)))-($H$14*($H$7*4096+$H$8*MIN(4096,$H$9))))/('Offload Refs'!$B$26*1000000000)*1000 -> 8.9910626 | F39: =(($H$14*($H$7*16384+$H$8*MIN(16384,$H$9)))-($H$14*($H$7*4096+$H$8*MIN(4096,$H$9))))/('Offload Refs'!$B$23*1000000000)*1000+(($H$14*($H$7*16384+$H$8*MIN(16384,$H$9)))-($H$14*($H$7*4096+$H$8*MIN(4096,$H$9))))/('Offload Refs'!$B$26*1000000000)*1000 -> 17.295784 | G39: =(($H$14*($H$7*16384+$H$8*MIN(16384,$H$9)))-($H$14*($H$7*4096+$H$8*MIN(4096,$H$9))))/('Offload Refs'!$B$24*1000000000)*1000+(($H$14*($H$7*16384+$H$8*MIN(16384,$H$9)))-($H$14*($H$7*4096+$H$8*MIN(4096,$H$9))))/('Offload Refs'!$B$26*1000000000)*1000 -> 40.592147 | H39: =(($H$14*($H$7*16384+$H$8*MIN(16384,$H$9)))-($H$14*($H$7*4096+$H$8*MIN(4096,$H$9))))/('Offload Refs'!$B$25*1000000000)*1000+(($H$14*($H$7*16384+$H$8*MIN(16384,$H$9)))-($H$14*($H$7*4096+$H$8*MIN(4096,$H$9))))/('Offload Refs'!$B$26*1000000000)*1000 -> 19.560709 | I39: =IF(MIN(E39:H39)<D39,"OFFLOAD delta wins","RECOMPUTE delta wins") -> OFFLOAD delta wins
A40: 4K -> 32K | B40: =(($H$14*($H$7*32768+$H$8*MIN(32768,$H$9)))-($H$14*($H$7*4096+$H$8*MIN(4096,$H$9))))/1073741824 -> 0.984375 | C40: =(((2*$H$5*1000000000*32768+4*$C$9*$H$13*($H$7*32768^2+$H$8*32768*MIN(32768,$H$9))))-((2*$H$5*1000000000*4096+4*$C$9*$H$13*($H$7*4096^2+$H$8*4096*MIN(4096,$H$9)))))/1000000000000 -> 448.85134 | D40: =(((2*$H$5*1000000000*32768+4*$C$9*$H$13*($H$7*32768^2+$H$8*32768*MIN(32768,$H$9))))-((2*$H$5*1000000000*4096+4*$C$9*$H$13*($H$7*4096^2+$H$8*4096*MIN(4096,$H$9)))))/($H$17*1000000000000)*1000 -> 1246.8093 | E40: =(($H$14*($H$7*32768+$H$8*MIN(32768,$H$9)))-($H$14*($H$7*4096+$H$8*MIN(4096,$H$9))))/('Offload Refs'!$B$22*1000000000)*1000+(($H$14*($H$7*32768+$H$8*MIN(32768,$H$9)))-($H$14*($H$7*4096+$H$8*MIN(4096,$H$9))))/('Offload Refs'!$B$26*1000000000)*1000 -> 20.979146 | F40: =(($H$14*($H$7*32768+$H$8*MIN(32768,$H$9)))-($H$14*($H$7*4096+$H$8*MIN(4096,$H$9))))/('Offload Refs'!$B$23*1000000000)*1000+(($H$14*($H$7*32768+$H$8*MIN(32768,$H$9)))-($H$14*($H$7*4096+$H$8*MIN(4096,$H$9))))/('Offload Refs'!$B$26*1000000000)*1000 -> 40.35683 | G40: =(($H$14*($H$7*32768+$H$8*MIN(32768,$H$9)))-($H$14*($H$7*4096+$H$8*MIN(4096,$H$9))))/('Offload Refs'!$B$24*1000000000)*1000+(($H$14*($H$7*32768+$H$8*MIN(32768,$H$9)))-($H$14*($H$7*4096+$H$8*MIN(4096,$H$9))))/('Offload Refs'!$B$26*1000000000)*1000 -> 94.71501 | H40: =(($H$14*($H$7*32768+$H$8*MIN(32768,$H$9)))-($H$14*($H$7*4096+$H$8*MIN(4096,$H$9))))/('Offload Refs'!$B$25*1000000000)*1000+(($H$14*($H$7*32768+$H$8*MIN(32768,$H$9)))-($H$14*($H$7*4096+$H$8*MIN(4096,$H$9))))/('Offload Refs'!$B$26*1000000000)*1000 -> 45.641654 | I40: =IF(MIN(E40:H40)<D40,"OFFLOAD delta wins","RECOMPUTE delta wins") -> OFFLOAD delta wins
A43: FORMULAS & METHOD
A44: Prefill FLOPs = 2 x P_active x T (projections + MLP/experts, linear in tokens) + 4 x causal x d_q x [dense_L x T^2 + window_L x T x min(T,window)] (attention scores, quadratic).
A45: P_active = ACTIVE params (MoE runs only active experts at prefill). d_q = Q_heads x head_dim. Windowed layers attend <= window keys, so their attention is ~linear, not T^2.
A46: Recompute time = Prefill FLOPs / (peak BF16 TFLOPS x achieved MFU). This is the compute-bound floor; real prefill also has memory-BW and kernel-launch overheads -> treat as optimistic.
A47: KV size (single seq) = 2 x KV_heads x head_dim x bytes x [dense_L x T + window_L x min(T,window)]. Windowed layers store only the window - the same saver as the sizing workbook.
A48: Load time = KV_bytes / media_BW (READ) + KV_bytes / PCIe_BW (WRITE to GPU). Serial sum shown; a pipelined DMA overlaps them, so the floor is max(read, write). For DRAM-resident KV the PCIe write dominates.
A49: Verdict uses the SELECTED accelerator's achieved TFLOPS. Concurrency cancels (it scales KV load and recompute equally), so the crossover is per-sequence and concurrency-independent.
...
