Workbook

Sheet Silicon
A1: Silicon Comparison — Compute, Memory & Interconnect
A2: Normalized to TFLOPS (compute) and GB / GB-per-second (memory) throughout. Dense = no structured sparsity applied; this is the honest baseline for serving-throughput math. Blank = not supported, or not yet disclosed by the vendor — never a guess. Source: Intel AI silicon comparison workbook (uploaded), cross-checked against vendor datasheets where cited.
A4: Silicon | B4: Category | C4: BF16 TFLOPS (dense) | D4: BF16 TFLOPS (w/ sparsity) | E4: FP8 TFLOPS (dense) | F4: FP8 TFLOPS (w/ sparsity) | G4: FP4/INT4 TFLOPS (dense) | H4: FP4/INT4 TFLOPS (w/ sparsity) | I4: Memory type | J4: Mem. bandwidth (GB/s) | K4: Mem. capacity (GB) | L4: PCIe lanes needed | M4: PCIe generation | N4: Notes / source
A5: Xeon 6737P | B5: CPU | C5: 95.03 | I5: DDR5-6400 RDIMM / DDR5-8000 MRDIMM, 8 channels | J5: 512 | L5: N/A — host CPU | M5: N/A | N5: BF16 via AMX. BW shown = MRDIMM figure (higher of RDIMM 409.6 / MRDIMM 512). Capacity is platform-dependent (up to 8 DIMMs/socket), not a fixed accelerator figure. Source: Xeon 6 SKU workbook, 32c/270W/2.9GHz base.
A6: Xeon 6767P | B6: CPU | C6: 170.39 | I6: DDR5-6400 RDIMM / DDR5-8000 MRDIMM, 8 channels | J6: 512 | L6: N/A — host CPU | M6: N/A | N6: BF16 via AMX. BW shown = MRDIMM figure. Capacity platform-dependent. Source: Xeon 6 SKU workbook, 64c/350W/2.6GHz base.
A7: Xeon 6972P | B7: CPU | C7: 235.93 | I7: DDR5-6400 RDIMM / DDR5-8800 MRDIMM, 12 channels | J7: 844.8 | L7: N/A — host CPU | M7: N/A | N7: BF16 via AMX. BW shown = MRDIMM figure (RDIMM 614.4 / MRDIMM 844.8). Capacity platform-dependent (up to 12 DIMMs/socket). Source: Xeon 6 SKU workbook, 96c/500W/2.4GHz base.
A8: Arc Pro B60 | B8: GPU | C8: 98.3 | I8: GDDR6, 192-bit | J8: 456 | K8: 24 | L8: x8 (x16 physical connector, x8 electrical) | M8: Gen 5.0 | N8: BF16 derived from XMX, assumed equal to FP16 (no separate BF16 spec published). Source: Intel Arc Pro B60 GPU Data Sheet v1.0.
A9: Arc Pro B70 | B9: GPU | C9: 183.5 | I9: GDDR6, ECC, 256-bit | J9: 608 | K9: 32 | L9: x16 | M9: Gen 5.0 | N9: BF16 derived from XMX rate. Source: Intel Arc Pro B70 published specs.
A10: Crescent Island | B10: GPU | C10: 655.5 | E10: 1311 | G10: 2622 | I10: LPDDR5X | J10: 1500 | K10: 160 | L10: x16 — assumed, not yet confirmed by Intel | M10: Gen 5.0 | N10: All figures Intel-published, no sparsity applied to any datatype on this part. Capacity: 160 GB reference design, 480 GB partner ceiling. Source: Intel Crescent Island Xe3P Technical Reference v1.0.
A11: NVIDIA H100 (PCIe) | B11: GPU | C11: 756 | D11: 1513 | E11: 1513 | F11: 3026 | I11: HBM2e | J11: 2039 | K11: 80 | L11: x16 | M11: Gen 5.0 | N11: Tensor Core dense/sparse pair as published. Source: NVIDIA H100 PCIe datasheet (public).
A12: NVIDIA H100 (SXM5) | B12: GPU | C12: 990 | D12: 1979 | E12: 1979 | F12: 3958 | I12: HBM3 | J12: 3350 | K12: 80 | L12: N/A — no PCIe host link (NVLink fabric) | M12: N/A | N12: 990 TFLOPS dense BF16 is this workbook's serving-math default (see Model Architecture sheet). Source: NVIDIA H100 SXM5 datasheet (public), HGX/DGX 8-GPU form factor.
A13: NVIDIA RTX PRO 6000 (Blackwell) | B13: GPU | C13: 251.9 | D13: 503.8 | E13: 503.8 | F13: 1007.6 | H13: 4000 | I13: GDDR7, ECC, 512-bit | J13: 1792 | K13: 96 | L13: x16 | M13: Gen 5.0 | N13: FP4 only published as a rounded ~4,000 TOPS sparse headline figure — no dense figure disclosed. Re-verify against nvidia.com before use in a bid.
A14: NVIDIA GB200 NVL72 (per GPU) | B14: GPU | D14: 5000 | F14: 10000 | H14: 20000 | I14: HBM3e | J14: 8000 | K14: 186 | L14: N/A — no PCIe host link (NVLink fabric) | M14: N/A | N14: Sold/benchmarked as a 36-CPU/72-GPU NVLink-fused rack; per-GPU figures derived by dividing published rack totals. No dense figures disclosed at any precision — sparse only. BW/capacity are per-GPU (576 TB/s and 13.4 TB aggregate across the rack). Re-verify before use in a bid.
A15: NVIDIA GB300 NVL72 (per GPU) | B15: GPU | D15: 5000 | F15: 10000 | G15: 15000 | H15: 20000 | I15: HBM3e | J15: 8000 | K15: 288 | L15: N/A — no PCIe host link (NVLink fabric) | M15: N/A | N15: FP4 (NVFP4) dense figure (15 PFLOPS/GPU) is explicitly published; BF16/FP8 dense are not. Third-party reporting on FP4 dense/sparse split is inconsistent for GB300 specifically — verify before use. BW/capacity per-GPU.
A16: SambaNova SN40L | B16: Accelerator | C16: 639 | I16: HBM3 (tier 1) + up to 1.5 TiB pluggable DDR (tier 2) | J16: 2000 | K16: 64 | L16: N/A — no PCIe host link | M16: N/A | N16: BF16 = midpoint of published 638–640 TFLOPS native PCU SIMD datapath, per socket. FP8 not a native SN40L datapath (arrives with SN50). Memory BW is a third-party estimate, not vendor-confirmed. Capacity shown = fast HBM3 tier only; DDR tier 2 (up to 1.5 TiB) is a slower second tier, not included in the GB figure.
A19: Interconnect Reference — all-reduce link bandwidth for tensor parallelism
A20: Interconnect | B20: Link BW (GB/s) | C20: Latency (µs/hop) | D20: Fabric type | E20: Notes
A21: NVLink 5 (GB200/GB300) | B21: 1800 | C21: 1.5 | D21: NVLink switch fabric | E21: Blackwell NVL72 rack, NVLink 5. Per-GPU aggregate bidirectional. Highest-bandwidth option for TP.
A22: NVLink 4 (H100 SXM5) | B22: 900 | C22: 2 | D22: NVLink switch fabric | E22: Hopper SXM5 / HGX-DGX 8-GPU. 18 links x 50 GB/s. The default for H100-class TP.
A23: NVLink 3 (A100 SXM4) | B23: 600 | C23: 2.5 | D23: NVLink switch fabric | E23: Ampere SXM4. 12 links x 50 GB/s.
A24: PCIe Gen5 x16 | B24: 64 | C24: 4 | D24: PCIe (host / P2P) | E24: Effective cross-GPU bandwidth without NVLink. ~1 order of magnitude below NVLink — TP prefill often becomes comm-bound here.
A25: PCIe Gen4 x16 | B25: 32 | C25: 5 | D25: PCIe (host / P2P) | E25: Older platform ceiling. Rarely a good TP-prefill fabric.
A26: InfiniBand NDR (400G) | B26: 50 | C26: 6 | D26: Network (inter-node) | E26: ~400 Gb/s = 50 GB/s per port. Inter-node TP is possible but latency + bandwidth make it a last resort vs intra-node NVLink.

Sheet Model Architecture
A1: Qwen3.8-27B — Model Architecture & Serving Inputs
A2: Source: huggingface.co/Qwen/Qwen3.8-27B (model card). Yellow cells are editable inputs; green cells are auto-pulled from the Silicon sheet. Every other sheet reads these via named ranges, so a single change here propagates everywhere.
A4: Serving Workload Parameters (shared across all calculation sheets)
A5: Parameter | B5: Value | C5: Unit | D5: Notes
A6: Concurrency (B) — max concurrent sequences | B6: 8 | C6: sequences | D6: Batch size / vLLM max_num_seqs
A7: Input tokens per sequence (L, prefill length) | B7: 8192 | C7: tokens | D7: Prompt length
A8: Output tokens per sequence (max generated) | B8: 1 | C8: tokens | D8: Max new tokens
A9: Decode context length (L_ctx) | B9: =B7+B8 -> 8193 | C9: tokens | D9: Context length at the decode step being costed. Default = input+output (end-of-generation, worst case). Overwrite with a fixed number to model an earlier point in generation.
A10: Weight dtype bytes/param | B10: 2 | C10: bytes | D10: BF16/FP16=2, FP8=1, INT4=0.5
A11: KV-cache dtype bytes/element | B11: 2 | C11: bytes | D11: BF16/FP16=2, FP8=1
A12: Activation / runtime overhead | B12: 0.12 | C12: fraction | D12: vLLM/SGLang workspace, CUDA graphs, block tables — engine dependent estimate
A13: Achievable compute efficiency | B13: 0.7 | C13: fraction | D13: Realistic % of peak FLOPS achieved by real kernels (launch overhead, imperfect overlap)
A14: DeltaNet kernel constant (c) | B14: 5 | C14: — | D14: Approximates extra matmuls in the chunked delta-rule update (correction/beta gate, chunk-local state, output readout). Kernel-dependent — validate against profiled kernel FLOPs.
A16: Silicon Selection (drives GPU peak TFLOPS + memory bandwidth for downstream calculations)
A17: Parameter | B17: Value | C17: Unit | D17: Notes
A18: Selected silicon | B18: Arc Pro B70 | C18: — | D18: Pick from the Silicon sheet (dropdown) — every downstream TFLOPS/GB figure below is pulled from that row.
A19: Compute precision | B19: BF16 | C19: — | D19: BF16, FP8, or FP4 — selects which dense TFLOPS column is pulled from the Silicon sheet.
A20: Peak TFLOPS (dense, pulled) | B20: =IF(B19="BF16",INDEX(Silicon!$C:$C,MATCH($B$18,Silicon!$A:$A,0)),IF(B19="FP8",INDEX(Silicon!$E:$E,MATCH($B$18,Silicon!$A:$A,0)),INDEX(Silicon!$G:$G,MATCH($B$18,Silicon!$A:$A,0)))) -> 183.5 | C20: TFLOPS | D20: Auto-pulled from Silicon sheet. Blank/0 result = vendor has not disclosed a dense figure at this precision for this part — pick a different precision or silicon.
A21: Memory bandwidth (pulled) | B21: =INDEX(Silicon!$J:$J,MATCH($B$18,Silicon!$A:$A,0)) -> 608 | C21: GB/s | D21: Auto-pulled from Silicon sheet.
A22: Memory capacity (pulled, reference) | B22: =INDEX(Silicon!$K:$K,MATCH($B$18,Silicon!$A:$A,0)) -> 32 | C22: GB | D22: Auto-pulled — single-chip VRAM/HBM capacity, used by the VRAM Calculation sheet's fit-check.
A23: Memory type (pulled, reference) | B23: =INDEX(Silicon!$I:$I,MATCH($B$18,Silicon!$A:$A,0)) -> GDDR6, ECC, 256-bit | C23: — | D23: Auto-pulled.
A24: Interconnect (pulled, reference) | B24: =INDEX(Silicon!$L:$L,MATCH($B$18,Silicon!$A:$A,0))&" — "&INDEX(Silicon!$M:$M,MATCH($B$18,Silicon!$A:$A,0)) -> x16 — Gen 5.0 | C24: — | D24: Auto-pulled PCIe lanes/generation, or NVLink note.
A26: Model Architecture Parameters — Qwen3.8-27B
A27: Parameter | B27: Value | C27: Unit | D27: Notes
A28: Total parameters | B28: 27.8 | C28: B params | D28: Dense (non-MoE), BF16 safetensors
A29: Total layers | B29: 64 | C29: layers | D29: 16 x (3x Gated DeltaNet + 1x Gated Attention)
A30: Full-attention layers | B30: 16 | C30: layers | D30: 1 of every 4 layers
A31: Gated DeltaNet layers | B31: 48 | C31: layers | D31: 3 of every 4 layers
A32: Hidden dimension | B32: 5120 | C32: —
A33: FFN intermediate dimension | B33: 17408 | C33: —
A34: Vocabulary size | B34: 248320 | C34: tokens | D34: Padded token embedding
A35: Native context length | B35: 262144 | C35: tokens
A36: Extended context length (YaRN) | B36: 1000000 | C36: tokens
A37: Full-attention: Q heads (n_q) | B37: 24 | C37: heads | D37: GQA
A38: Full-attention: KV heads | B38: 4 | C38: heads | D38: GQA, 6:1 Q:KV ratio
A39: Full-attention: head dimension | B39: 256 | C39: —
A40: Full-attention: RoPE dimension | B40: 64 | C40: —
A41: DeltaNet: V heads | B41: 48 | C41: heads
A42: DeltaNet: QK heads | B42: 16 | C42: heads
A43: DeltaNet: head dimension | B43: 128 | C43: — | D43: Used for both K and V dims of the recurrent state matrix
...

Sheet VRAM Calculation
A1: VRAM Calculation
A2: All inputs pulled from 'Model Architecture'. Change Concurrency, InputTokens, OutputTokens or dtypes there and every value below recalculates. Units normalized to GB (decimal, 1e9 bytes) throughout, matching vendor-quoted capacity figures on the Silicon sheet.
A4: # | B4: Component | C4: Description | D4: Algebraic Formula | E4: Value | F4: Unit | G4: Notes / Source
A5: 1 | B5: Model weights | C5: Total weight memory — constant, independent of concurrency or context length | D5: N x weight_dtype_bytes / 1e9 | E5: =Params*WeightBytes/1000000000 -> 55.6 | F5: GB | G5: N = Params named range (ParamsB x 1e9)
A6: 2 | B6: KV cache — full-attention layers | C6: Grows with concurrency x (input+output tokens); only the 16 full-attention layers hold a growing cache | D6: 2 x kv_heads x head_dim x kv_bytes x full_attn_layers x concurrency x (input_tok+output_tok) / 1e9 | E6: =2*KvHeads*HeadDim*KVBytes*FullAttnLayers*Concurrency*(InputTokens+OutputTokens)/1000000000 -> 4.2954916 | F6: GB | G6: 2x = separate K and V tensors
A7: 3 | B7: KV cache — DeltaNet recurrent state | C7: Fixed-size state per sequence; scales with concurrency only, NOT with context length (this is the hybrid-architecture saving) | D7: v_heads x head_dim^2 x kv_bytes x delta_layers x concurrency / 1e9 | E7: =VHeads*DHeadDim^2*KVBytes*DeltaNetLayers*Concurrency/1000000000 -> 0.60397978 | F7: GB | G7: State matrix per head is head_dim x head_dim (K-dim x V-dim, both = DHeadDim)
A8: 4 | B8: Subtotal (weights + KV cache) | C8: Sum of rows 1-3 | D8: row1 + row2 + row3 | E8: =E5+E6+E7 -> 60.499471 | F8: GB
A9: 5 | B9: Activation / runtime overhead | C9: CUDA graphs, workspace buffers, PagedAttention block-table overhead — engine-dependent margin | D9: subtotal x overhead_pct | E9: =E8*OverheadPct -> 7.2599366 | F9: GB | G9: OverheadPct is an editable assumption on sheet 1, not a first-principles term
A10: 6 | B10: TOTAL VRAM REQUIRED | C10: Sum of subtotal + overhead | D10: subtotal + overhead | E10: =E8+E9 -> 67.759408 | F10: GB | G10: This is the number to size GPU count/type against
A12: GPU capacity check
A13: GPU config | B13: VRAM capacity (GB) | D13: Fits? (capacity >= total required)
A14: Selected silicon (from Model Architecture) | B14: =SelectedSiliconCapacityGB -> 32 | D14: =IF(B14>=$E$10,"Yes — single chip","No — needs multiple chips / tensor-parallel") -> No — needs multiple chips / tensor-parallel
A15: 1x RTX 4090 / L4 | B15: 24 | D15: =IF(B15>=$E$10,"Yes","No") -> No
A16: 1x L40S | B16: 48 | D16: =IF(B16>=$E$10,"Yes","No") -> No
A17: 1x A100 80GB / H100 | B17: 80 | D17: =IF(B17>=$E$10,"Yes","No") -> Yes
A18: 1x H200 | B18: 141 | D18: =IF(B18>=$E$10,"Yes","No") -> Yes
A19: 1x MI300X | B19: 192 | D19: =IF(B19>=$E$10,"Yes","No") -> Yes
A20: 2x H100 | B20: 160 | D20: =IF(B20>=$E$10,"Yes","No") -> Yes
A21: 4x H100 | B21: 320 | D21: =IF(B21>=$E$10,"Yes","No") -> Yes
A22: 8x H100 | B22: 640 | D22: =IF(B22>=$E$10,"Yes","No") -> Yes

Sheet Prefill TFLOPs
A1: Prefill FLOPs / TFLOPS Calculation
A2: Prefill processes the full prompt (InputTokens) in one pass across Concurrency sequences. Full-attention layers cost O(L^2); DeltaNet layers cost O(L). All compute terms are expressed directly in TFLOP (FLOPs / 1e12), consistent with the Silicon sheet's TFLOPS units.
A4: # | B4: Component | C4: Description | D4: Algebraic Formula | E4: Value | F4: Unit | G4: Notes / Source
A5: 1 | B5: Dense term (all layers) | C5: Every weight matrix (QKVO projections + FFN) touched once per token, standard 2xparamsxtokens approximation | D5: 2 x N x L x B / 1e12 | E5: =2*Params*InputTokens*Concurrency/1000000000000 -> 3643.8016 | F5: TFLOP | G5: N=Params, L=InputTokens, B=Concurrency
A6: 2 | B6: Full-attention term (16 layers) — O(L^2) | C6: QK^T + softmax.V per head, halved for causal masking (avg query attends to L/2 keys) | D6: 2 x n_q x head_dim x L^2 x B x full_attn_layers / 1e12 | E6: =2*Nq*HeadDim*InputTokens^2*Concurrency*FullAttnLayers/1000000000000 -> 105.55312 | F6: TFLOP | G6: Quadratic in prompt length — dominant term at long context
A7: 3 | B7: DeltaNet term (48 layers) — O(L) | C7: Chunked parallel-scan delta-rule update used at prefill time; linear in sequence length | D7: c x v_heads x head_dim^2 x L x B x delta_layers / 1e12 | E7: =CConst*VHeads*DHeadDim^2*InputTokens*Concurrency*DeltaNetLayers/1000000000000 -> 12.369506 | F7: TFLOP | G7: c is a kernel-dependent constant set on sheet 1 — validate against profiled kernel
A8: 4 | B8: TOTAL PREFILL COMPUTE | C8: Sum of rows 1-3 | D8: row1 + row2 + row3 | E8: =E5+E6+E7 -> 3761.7242 | F8: TFLOP
A9: 5 | B9: Estimated compute time | C9: Assumes prefill is compute-bound (high arithmetic intensity — see explanation below). TFLOP / (TFLOPS x efficiency) = seconds directly, no unit conversion needed. | D9: total_TFLOP / (peak_TFLOPS x efficiency) | E9: =E8/(PeakTFLOPS*EffComputeMFU) -> 45.758615 | F9: seconds | G9: Now uses Effective compute MFU (GEMM MFU x hybrid+stack derate), not the old flat efficiency.
A10: 6 | B10: Achieved TFLOPS | C10: Back-calculated throughput at the estimated compute time | D10: total_TFLOP / time | E10: =E8/E9 -> 82.208 | F10: TFLOPS | G10: Should equal peak_TFLOPS x efficiency by construction — sanity check
A12: Why prefill is compute-bound (context, not a computed row)
A13: With B x L tokens processed in one pass, each weight read from HBM is reused across many tokens, so arithmetic intensity (FLOPs per byte moved) is high. Throughput therefore tracks GPU peak FLOPS reasonably well — the O(L^2) full-attention term is what erodes that efficiency as prompt length grows. Contrast with the Decode-BW sheet, where a single new token per sequence means intensity collapses and bandwidth dominates instead.

Sheet Prefill TP
A1: Prefill under Tensor Parallelism — compute + communication
A2: Compute shards across TP GPUs (near-ideal, prefill is compute-bound). Communication adds 2 all-reduces/layer on the [B x L x hidden] activation tensor — cost set by the selected interconnect. TP degree and interconnect are chosen on the Model Architecture sheet. All compute in TFLOP, all data volume in GB, times in seconds.
A4: A. Single-GPU baseline (un-sharded)
A5: # | B5: Component | C5: Description | D5: Algebraic Formula | E5: Value | F5: Unit | G5: Notes / Source
A6: A1 | B6: Total prefill compute | C6: Pulled from the Prefill TFLOPs sheet (row 4: dense + O(L^2) attention + O(L) DeltaNet) | D6: Prefill TFLOPs!total (row 4) | E6: ='Prefill TFLOPs'!E8 -> 3761.7242 | F6: TFLOP | G6: Same workload (B, L) as everywhere else
A7: A2 | B7: Single-GPU compute time | C7: Whole model on one card, compute-bound | D7: total_TFLOP / (peak_TFLOPS x efficiency) | E7: =E6/(PeakTFLOPS*EffComputeMFU) -> 45.758615 | F7: seconds | G7: The reference point for speedup. No communication on 1 GPU.
A9: B. Compute at the selected TP degree
A10: # | B10: Component | C10: Description | D10: Algebraic Formula | E10: Value | F10: Unit | G10: Notes / Source
A11: B1 | B11: Per-GPU compute | C11: Every FLOP term (weights + heads) shards across TP GPUs | D11: total_TFLOP / TP | E11: =E6/TP -> 940.43106 | F11: TFLOP/GPU | G11: Weights sharded (Megatron col/row split); attention + DeltaNet sharded by heads
A12: B2 | B12: Per-GPU compute time | C12: Sharded compute, still compute-bound | D12: (total_TFLOP / TP) / (peak_TFLOPS x efficiency) | E12: =E11/(PeakTFLOPS*EffComputeMFU) -> 11.439654 | F12: seconds | G12: This is T_compute(TP). Divides ~linearly with TP.
A14: C. Communication — ring all-reduce cost
A15: # | B15: Component | C15: Description | D15: Algebraic Formula | E15: Value | F15: Unit | G15: Notes / Source
A16: C1 | B16: All-reduce message size | C16: The activation tensor reduced after each sublayer | D16: B x L x hidden x act_bytes / 1e9 | E16: =Concurrency*InputTokens*HiddenComm*ActBytes/1000000000 -> 0.67108864 | F16: GB | G16: Independent of layer type — DeltaNet and full-attn layers all-reduce the same [B,L,hidden]
A17: C2 | B17: Number of all-reduces | C17: collective ops per layer x total layers | D17: coll_per_layer x total_layers | E17: =CollPerLayer*TotalLayers -> 128 | F17: all-reduces | G17: Standard Megatron TP: 2/layer x 64 layers = 128
A18: C3 | B18: Bandwidth term (per all-reduce) | C18: Ring all-reduce data movement per GPU | D18: 2 x (TP-1)/TP x msg_GB / link_BW_GBs | E18: =IF(TP<=1,0,2*(TP-1)/TP*E16/(LinkBW*CommEff)) -> 0.018504282 | F18: seconds | G18: Dominant term for large prefill activation tensors
A19: C4 | B19: Latency term (per all-reduce) | C19: Ring hop latency, 2(TP-1) hops | D19: 2 x (TP-1) x latency_us / 1e6 | E19: =IF(TP<=1,0,2*(TP-1)*LinkLat/1000000) -> 2.4e-05 | F19: seconds | G19: Small vs bandwidth term when messages are large
A20: C5 | B20: Total communication time | C20: All all-reduces across the whole forward pass | D20: n_all_reduces x (bw_term + latency_term) | E20: =E17*(E18+E19) -> 2.3716201 | F20: seconds | G20: This is T_comm(TP). Zero at TP=1.
A22: D. Wall-clock, speedup & parallel efficiency
A23: # | B23: Component | C23: Description | D23: Algebraic Formula | E23: Value | F23: Unit | G23: Notes / Source
A24: D1 | B24: Prefill wall-clock (no overlap) | C24: All-reduce is a hard sync point in vanilla TP, so compute + comm are additive | D24: (T_compute + T_comm) x (1 + overhead) | E24: =(E12+E20)*(1+OverheadPct) -> 15.468627 | F24: seconds | G24: Overhead (0.12) now applied here — previously omitted from the prefill wall-clock.
A25: D2 | B25: Speedup vs 1 GPU | C25: How much faster than the single-GPU baseline | D25: T_single / T_total(TP) | E25: =E7/E24 -> 2.9581563 | F25: x | G25: Ideal would be = TP; the gap is the communication tax
A26: D3 | B26: Parallel efficiency | C26: Speedup as a fraction of the ideal linear speedup | D26: speedup / TP | E26: =E25/TP -> 0.73953906 | F26: fraction | G26: >0.8 is healthy; <0.55 means the interconnect is eating the gains
A27: D4 | B27: Regime verdict | C27: Which side dominates at this TP + interconnect | D27: IF(T_comm > T_compute, "Communication-bound", "Compute-bound scaling") | E27: =IF(E20>E12,"Communication-bound — adding GPUs mostly buys memory, not speed","Compute-bound scaling — TP still buying real speedup") -> Compute-bound scaling — TP still buying real speedup | F27: —
A29: E. TP sweep — where scaling breaks down (independent of the selected TP above)
A30: TP | B30: Per-GPU compute (s) | C30: Comm (s) | D30: Total (s) | E30: Speedup (x) | F30: Parallel efficiency | G30: Regime
A31: 1 | B31: =E6/1/(PeakTFLOPS*EffComputeMFU) -> 45.758615 | C31: =0 -> 0 | D31: =(B31+C31)*(1+OverheadPct) -> 51.249649 | E31: =$E$7/D31 -> 0.89285714 | F31: =E31/A31 -> 0.89285714 | G31: =IF(C31>B31,"comm-bound","compute-bound") -> compute-bound
A32: 2 | B32: =E6/2/(PeakTFLOPS*EffComputeMFU) -> 22.879308 | C32: =(CollPerLayer*TotalLayers)*(2*(2-1)/2*E16/(LinkBW*CommEff) + 2*(2-1)*LinkLat/1000000) -> 1.5800561 | D32: =(B32+C32)*(1+OverheadPct) -> 27.394487 | E32: =$E$7/D32 -> 1.6703585 | F32: =E32/A32 -> 0.83517926 | G32: =IF(C32>B32,"comm-bound","compute-bound") -> compute-bound
A33: 4 | B33: =E6/4/(PeakTFLOPS*EffComputeMFU) -> 11.439654 | C33: =(CollPerLayer*TotalLayers)*(2*(4-1)/4*E16/(LinkBW*CommEff) + 2*(4-1)*LinkLat/1000000) -> 2.3716201 | D33: =(B33+C33)*(1+OverheadPct) -> 15.468627 | E33: =$E$7/D33 -> 2.9581563 | F33: =E33/A33 -> 0.73953906 | G33: =IF(C33>B33,"comm-bound","compute-bound") -> compute-bound
A34: 8 | B34: =E6/8/(PeakTFLOPS*EffComputeMFU) -> 5.7198269 | C34: =(CollPerLayer*TotalLayers)*(2*(8-1)/8*E16/(LinkBW*CommEff) + 2*(8-1)*LinkLat/1000000) -> 2.7704742 | D34: =(B34+C34)*(1+OverheadPct) -> 9.5091372 | E34: =$E$7/D34 -> 4.812068 | F34: =E34/A34 -> 0.6015085 | G34: =IF(C34>B34,"comm-bound","compute-bound") -> compute-bound
A35: 16 | B35: =E6/16/(PeakTFLOPS*EffComputeMFU) -> 2.8599134 | C35: =(CollPerLayer*TotalLayers)*(2*(16-1)/16*E16/(LinkBW*CommEff) + 2*(16-1)*LinkLat/1000000) -> 2.9760452 | D35: =(B35+C35)*(1+OverheadPct) -> 6.5362736 | E35: =$E$7/D35 -> 7.000719 | F35: =E35/A35 -> 0.43754494 | G35: =IF(C35>B35,"comm-bound","compute-bound") -> comm-bound
A37: Assumptions to validate
A38: 1) COMPUTE-COMM OVERLAP: wall-clock (D1) assumes NO overlap (additive). Real TP implementations overlap some communication with compute; the true time lies between D1 and pure per-GPU compute (B2). 2) HYBRID ARCHITECTURE DOES NOT HELP COMMS: every one of the 64 layers all-reduces the same [B,L,hidden] activation regardless of whether it is a DeltaNet or a full-attention layer — unlike the KV-cache saving, TP communication scales with ALL layers. DeltaNet recurrent state shards by head and needs no extra cross-GPU exchange, so it is no worse than attention, just not better. 3) KV-HEAD SHARDING CEILING: the attention layers have only 4 KV heads, so they shard cleanly only to TP=4. At TP=8 each KV head is replicated across 2 GPUs (standard in vLLM) — correct, but costs a little redundant KV memory. Q heads (24) and DeltaNet heads (48/16) shard cleanly to TP=8+. 4) RING ALL-REDUCE MODEL: assumes a bandwidth-optimal ring collective at the selected link bandwidth. Real NCCL achieves ~70-85% of theoretical; scale LinkBW down accordingly for a conservative estimate. 5) COMPUTE:COMM RATIO IS ~INDEPENDENT OF B and L for the dense term (both scale with B*L). The O(L^2) attention term adds compute without adding comm, so LONG-context prefill is MORE TP-friendly — raise L on the Model Architecture sheet to see efficiency improve. 6) INTER-NODE: the InfiniBand row models cross-node TP, which is usually avoided — keep TP within an NVLink island and use pipeline/data parallelism across nodes.

Sheet Prefill Calibration
A1: Prefill Calibration — model vs. measured (TP4, Arc Pro B70)
A2: Back out the ACHIEVED TFLOPS/GPU from real runs, and check the refactored model against them. The 'Measured TTFT' column is editable (yellow) — paste your own runs. The hybrid+stack derate on the Model Architecture sheet is the single knob to fit; once fit at one point it should track the others because achieved throughput is ~flat in concurrency. Compute in TFLOP, times in seconds.
A4: A. Achieved throughput implied by measured TTFT
A5: # | B5: Concurrency B | C5: Measured TTFT (s) | D5: Total FLOP (TFLOP) | E5: Per-GPU FLOP (TFLOP) | F5: Achieved TFLOPS/GPU | G5: Achieved MFU (vs peak) | H5: Model TTFT (s) | I5: Model error
A6: 1 | B6: 1 | C6: 2.02844 | D6: =(2*Params*InputTokens*B6 + 2*Nq*HeadDim*InputTokens^2*B6*FullAttnLayers + CConst*VHeads*DHeadDim^2*InputTokens*B6*DeltaNetLayers)/1000000000000 -> 470.21553 | E6: =D6/TP -> 117.55388 | F6: =E6/C6 -> 57.952851 | G6: =F6/PeakTFLOPS -> 0.31581935 | H6: =(E6/(PeakTFLOPS*EffComputeMFU) + (CollPerLayer*TotalLayers)*(2*(TP-1)/TP*(B6*InputTokens*HiddenComm*ActBytes/1000000000)/(LinkBW*CommEff) + 2*(TP-1)*LinkLat/1000000))*(1+OverheadPct) -> 1.9365889 | I6: =(H6-C6)/C6 -> -0.045281643
A7: 2 | B7: 2 | C7: 3.75776 | D7: =(2*Params*InputTokens*B7 + 2*Nq*HeadDim*InputTokens^2*B7*FullAttnLayers + CConst*VHeads*DHeadDim^2*InputTokens*B7*DeltaNetLayers)/1000000000000 -> 940.43106 | E7: =D7/TP -> 235.10776 | F7: =E7/C7 -> 62.565934 | G7: =F7/PeakTFLOPS -> 0.34095877 | H7: =(E7/(PeakTFLOPS*EffComputeMFU) + (CollPerLayer*TotalLayers)*(2*(TP-1)/TP*(B7*InputTokens*HiddenComm*ActBytes/1000000000)/(LinkBW*CommEff) + 2*(TP-1)*LinkLat/1000000))*(1+OverheadPct) -> 3.8697372 | I7: =(H7-C7)/C7 -> 0.029798915
A8: 3 | B8: 4 | C8: 7.36066 | D8: =(2*Params*InputTokens*B8 + 2*Nq*HeadDim*InputTokens^2*B8*FullAttnLayers + CConst*VHeads*DHeadDim^2*InputTokens*B8*DeltaNetLayers)/1000000000000 -> 1880.8621 | E8: =D8/TP -> 470.21553 | F8: =E8/C8 -> 63.882251 | G8: =F8/PeakTFLOPS -> 0.34813216 | H8: =(E8/(PeakTFLOPS*EffComputeMFU) + (CollPerLayer*TotalLayers)*(2*(TP-1)/TP*(B8*InputTokens*HiddenComm*ActBytes/1000000000)/(LinkBW*CommEff) + 2*(TP-1)*LinkLat/1000000))*(1+OverheadPct) -> 7.7360337 | I8: =(H8-C8)/C8 -> 0.050997288
A9: 4 | B9: 8 | C9: 15.48305 | D9: =(2*Params*InputTokens*B9 + 2*Nq*HeadDim*InputTokens^2*B9*FullAttnLayers + CConst*VHeads*DHeadDim^2*InputTokens*B9*DeltaNetLayers)/1000000000000 -> 3761.7242 | E9: =D9/TP -> 940.43106 | F9: =E9/C9 -> 60.739393 | G9: =F9/PeakTFLOPS -> 0.33100487 | H9: =(E9/(PeakTFLOPS*EffComputeMFU) + (CollPerLayer*TotalLayers)*(2*(TP-1)/TP*(B9*InputTokens*HiddenComm*ActBytes/1000000000)/(LinkBW*CommEff) + 2*(TP-1)*LinkLat/1000000))*(1+OverheadPct) -> 15.468627 | I9: =(H9-C9)/C9 -> -0.00093155039
A10: 5 | B10: 16 | C10: 29.4712 | D10: =(2*Params*InputTokens*B10 + 2*Nq*HeadDim*InputTokens^2*B10*FullAttnLayers + CConst*VHeads*DHeadDim^2*InputTokens*B10*DeltaNetLayers)/1000000000000 -> 7523.4484 | E10: =D10/TP -> 1880.8621 | F10: =E10/C10 -> 63.820344 | G10: =F10/PeakTFLOPS -> 0.34779479 | H10: =(E10/(PeakTFLOPS*EffComputeMFU) + (CollPerLayer*TotalLayers)*(2*(TP-1)/TP*(B10*InputTokens*HiddenComm*ActBytes/1000000000)/(LinkBW*CommEff) + 2*(TP-1)*LinkLat/1000000))*(1+OverheadPct) -> 30.933813 | I10: =(H10-C10)/C10 -> 0.049628548
A11: 6 | B11: 32 | C11: 56.99582 | D11: =(2*Params*InputTokens*B11 + 2*Nq*HeadDim*InputTokens^2*B11*FullAttnLayers + CConst*VHeads*DHeadDim^2*InputTokens*B11*DeltaNetLayers)/1000000000000 -> 15046.897 | E11: =D11/TP -> 3761.7242 | F11: =E11/C11 -> 66.000002 | G11: =F11/PeakTFLOPS -> 0.35967303 | H11: =(E11/(PeakTFLOPS*EffComputeMFU) + (CollPerLayer*TotalLayers)*(2*(TP-1)/TP*(B11*InputTokens*HiddenComm*ActBytes/1000000000)/(LinkBW*CommEff) + 2*(TP-1)*LinkLat/1000000))*(1+OverheadPct) -> 61.864185 | I11: =(H11-C11)/C11 -> 0.085416178
B13: Mean achieved MFU | G13: =AVERAGE(G6:G11) -> 0.34056383 | H13: Mean |error| | I13: =SUMPRODUCT(ABS(H6:H11-C6:C11)/C6:C11)/6 -> 0.043675687
A15: B. Where the time goes at the selected operating point (Concurrency from Model Architecture)
B16: Compute time (Eff compute MFU) | F16: ='Prefill TP'!E12 -> 11.439654 | G16: seconds — dense GEMM + attention at the effective compute MFU
B17: Communication time (all-reduce, comm-eff derated) | F17: ='Prefill TP'!E20 -> 2.3716201 | G17: seconds — 128 all-reduces over the selected fabric
B18: Subtotal | F18: ='Prefill TP'!E12+'Prefill TP'!E20 -> 13.811274 | G18: seconds — before overhead
B19: Overhead (x OverheadPct) | F19: =('Prefill TP'!E12+'Prefill TP'!E20)*OverheadPct -> 1.6573529 | G19: seconds — runtime/workspace/graph overhead, now applied
B20: MODEL PREFILL WALL-CLOCK (TTFT) | F20: ='Prefill TP'!E24 -> 15.468627 | G20: seconds — compare to your measured TTFT at this B
A22: How to use / what this captures
A23: The gap between the old FLOP-only model (~9.3 s) and reality (15.5 s) is almost entirely COMPUTE efficiency, not communication: backing achieved throughput out of every measured row gives a near-constant ~60-66 TFLOPS/GPU = ~33% of the B70's 183.5 peak, versus the 0.70 the old model assumed. A pure dense-transformer prefill really is ~all-GEMM and the old model works for it; this model is 3/4 Gated DeltaNet layers whose chunked recurrent scan, convs, norms, gates and RoPE burn wall-clock far out of proportion to their tiny FLOP share (DeltaNet is 0.33% of FLOPs but a large share of time). The 'hybrid+stack compute derate' lumps that together with kernel-launch overhead and XPU/vLLM maturity. A single measured point can't uniquely separate compute-derate from comm-efficiency (both scale ~linearly with B) — to split them, profile one run (e.g. vLLM XPU profiler): measure the all-reduce time directly, set Communication efficiency from it, then let the derate absorb the remaining compute gap. The derate is ~shape-stable in B but should be re-checked when L or TP change materially.

Sheet Decode TFLOPs
A1: Decode FLOPs / TFLOPS Calculation (per token-generation step)
A2: Decode generates ONE new token per sequence per step, attending against DecodeContextLen already-cached tokens. Full-attention cost collapses from O(L^2) to O(L_ctx); DeltaNet stays O(1). All compute terms expressed directly in TFLOP, consistent with the Silicon sheet's TFLOPS units.
A4: # | B4: Component | C4: Description | D4: Algebraic Formula | E4: Value | F4: Unit | G4: Notes / Source
A5: 1 | B5: Dense term (per step) | C5: Same weight matrices as prefill, but only 1 new token per sequence this step | D5: 2 x N x B / 1e12 | E5: =2*Params*Concurrency/1000000000000 -> 0.4448 | F5: TFLOP
A6: 2 | B6: Full-attention term (16 layers) — O(L_ctx) | C6: 1 new query attends to L_ctx cached keys — no causal-mask halving needed (every key is valid) | D6: 2 x n_q x head_dim x L_ctx x B x full_attn_layers / 1e12 | E6: =2*Nq*HeadDim*DecodeContextLen*Concurrency*FullAttnLayers/1000000000000 -> 0.012886475 | F6: TFLOP | G6: Linear in context length, not quadratic — quadratic cost was already paid at prefill
A7: 3 | B7: DeltaNet term (48 layers) — O(1) | C7: Fixed-size recurrent state update — completely independent of context length | D7: c x v_heads x head_dim^2 x B x delta_layers / 1e12 | E7: =CConst*VHeads*DHeadDim^2*Concurrency*DeltaNetLayers/1000000000000 -> 0.0015099494 | F7: TFLOP | G7: No L_ctx term at all — this is the structural saving of the hybrid design
A8: 4 | B8: TOTAL DECODE COMPUTE / step | C8: Sum of rows 1-3 | D8: row1 + row2 + row3 | E8: =E5+E6+E7 -> 0.45919642 | F8: TFLOP
A9: 5 | B9: Estimated compute time / step | C9: Compute-bound estimate only — see Decode-BW sheet for the bandwidth-bound estimate, which is usually the binding constraint | D9: total_TFLOP / (peak_TFLOPS x efficiency) | E9: =E8/(PeakTFLOPS*Efficiency) -> 0.003574904 | F9: seconds
A10: 6 | B10: Achieved TFLOPS (compute-bound assumption) | C10: Back-calculated from the compute-bound time above | D10: total_TFLOP / time | E10: =E8/E9 -> 128.45 | F10: TFLOPS | G10: In practice decode rarely hits this — cross-check against Decode-BW sheet
A12: Important caveat (context, not a computed row)
A13: This sheet's 'estimated compute time' assumes decode is compute-bound, which is almost never true at low concurrency. At B=1, decode FLOPs are tiny (~2xN) but the ENTIRE weight set must still be streamed from HBM to produce one token — arithmetic intensity is very low, far below any modern GPU's compute:bandwidth ridge point. See the 'Decode BW' sheet for the bandwidth-bound time, which is the realistic binding constraint, and the roofline verdict that picks whichever is larger.

Sheet Decode Multi-Node
A1: Decode across Multiple Nodes — TP vs PP vs DP
A2: Decode is bandwidth-bound and latency-sensitive; crossing a node boundary attacks time-per-output-token (TPOT), not FLOPs. This sheet compares the three ways to span nodes against the same per-token baseline. Inter-node fabric + PP/DP knobs are on the Model Architecture sheet. Times in ms/token, throughput in tokens/s.
A4: A. Single-node decode baseline (per output token)
A5: # | B5: Component | C5: Description | D5: Algebraic Formula | E5: Value | F5: Unit | G5: Notes / Source
A6: A1 | B6: Bytes moved / token | C6: Weights + KV (16 attn layers) + DeltaNet state (48 layers) — pulled from the Decode BW sheet | D6: Decode BW!total_bytes (row 4) | E6: ='Decode BW'!E8 -> 60.499471 | F6: GB | G6: Bandwidth-bound: this is what sets the step time
A7: A2 | B7: Intra-node aggregate bandwidth | C7: Per-GPU HBM BW x intra-node TP (all TP GPUs stream weights/KV in parallel) | D7: mem_bandwidth_GBs x intra_TP | E7: =BandwidthGBs*IntraTP -> 4864 | F7: GB/s | G7: TP shards weights+KV, so effective BW scales with TP within the node
A8: A3 | B8: Baseline step time (bandwidth-bound) | C8: Time to move the per-token bytes at aggregate intra-node BW | D8: bytes_per_token / agg_bandwidth x 1000 | E8: =E6/E7*1000 -> 12.438214 | F8: ms/token | G8: The floor TPOT before any inter-node penalty. (Bytes shard across TP, so bytes/agg_BW = per-GPU bytes / per-GPU BW.)
A10: B. Scenario 1 — Tensor parallelism ACROSS nodes (usually the wrong choice)
A11: # | B11: Component | C11: Description | D11: Algebraic Formula | E11: Value | F11: Unit | G11: Notes / Source
A12: B1 | B12: All-reduce message / token | C12: One new token per sequence -> activation is [B x 1 x hidden], tiny | D12: B x 1 x hidden x act_bytes / 1e9 | E12: =Concurrency*HiddenComm*ActBytes/1000000000 -> 8.192e-05 | F12: GB | G12: ~0.0003 GB at B=32 — bandwidth is NOT the problem here, latency is
A13: B2 | B13: All-reduces / token | C13: 2 per layer x all layers — paid EVERY token | D13: coll_per_layer x total_layers | E13: =CollPerLayer*TotalLayers -> 128 | F13: collectives | G13: 128 hard syncs on the critical path per token
A14: B3 | B14: Total TP degree (spanning nodes) | C14: Intra-node TP x nodes — the ring now crosses the slow fabric | D14: intra_TP x nodes | E14: =IntraTP*Nodes -> 16 | F14: GPUs | G14: The all-reduce ring includes inter-node hops
A15: B4 | B15: Inter-node collective time / token | C15: Ring all-reduce over the INTER-NODE fabric, latency-dominated for tiny messages | D15: n_AR x [ 2(TP-1)/TP x msg/inter_BW + 2(TP-1) x inter_lat ] | E15: =E13*(2*(E14-1)/E14*E12/InterBW + 2*(E14-1)*InterLat/1000000)*1000 -> 23.433216 | F15: ms/token | G15: This is added ON TOP of the compute step, every token
A16: B5 | B16: TP-across-nodes TPOT | C16: Baseline step + inter-node collective penalty | D16: baseline_step + inter_node_collective_time | E16: =E8+E15 -> 35.87143 | F16: ms/token | G16: Compare against baseline — the delta is pure latency loss
A18: C. Scenario 2 — Pipeline parallelism ACROSS nodes (workable for throughput)
A19: # | B19: Component | C19: Description | D19: Algebraic Formula | E19: Value | F19: Unit | G19: Notes / Source
A20: C1 | B20: Stage-boundary sends / token | C20: PP only ships activations at stage boundaries — point-to-point, not collectives | D20: pp_stages - 1 | E20: =PPStages-1 -> 1 | F20: sends | G20: One [B x 1 x hidden] send per boundary per token
A21: C2 | B21: Handoff latency / token | C21: Serial traversal of stage boundaries across the inter-node fabric | D21: (pp_stages-1) x (msg/inter_BW + inter_lat) | E21: =E20*(E12/InterBW + InterLat/1000000)*1000 -> 0.0076384 | F21: ms/token | G21: Far fewer inter-node ops than TP (boundaries, not 128 collectives)
A22: C3 | B22: Pipeline bubble factor | C22: Fraction of time a stage idles waiting for work; shrinks with more in-flight microbatches | D22: (pp_stages - 1) / in_flight_microbatches | E22: =(PPStages-1)/PPMicro -> 0.125 | F22: fraction | G22: Continuous batching supplies microbatches to hide the bubble
A23: C4 | B23: PP-across-nodes TPOT | C23: Baseline step inflated by the bubble, plus serial handoff latency | D23: baseline_step x (1 + bubble) + handoff_latency | E23: =E8*(1+E22)+E21 -> 14.000629 | F23: ms/token | G23: A token still traverses all stages serially; depth adds latency but comms shape fits a slow fabric
A25: D. Scenario 3 — Data parallelism / replication (best fit for a 27.8B model)
A26: # | B26: Component | C26: Description | D26: Algebraic Formula | E26: Value | F26: Unit | G26: Notes / Source
A27: D1 | B27: Replicas | C27: Whole model fits per node -> replicate and route requests. Zero forward-pass inter-node traffic. | D27: nodes (1 replica per node, intra-node TP inside) | E27: 2 | F27: replicas | G27: Model weights (55.6 GB BF16) fit in a single 80GB GPU/node
A28: D2 | B28: DP TPOT | C28: Per-token latency identical to single node — no inter-node sync in the forward pass | D28: baseline_step (unchanged) | E28: =E8 -> 12.438214 | F28: ms/token | G28: Latency is not degraded; you scale throughput, not per-token speed
A29: D3 | B29: Aggregate throughput | C29: Per-replica throughput x replicas — linear scaling | D29: (concurrency / TPOT_seconds) x replicas | E29: =(Concurrency/(E28/1000))*E27 -> 1286.3583 | F29: tokens/s | G29: The metric DP actually improves
A31: E. Side-by-side — TPOT and per-token inter-node penalty
A32: Strategy | B32: TPOT (ms/token) | C32: vs baseline | D32: Inter-node ops/token | E32: Comms shape | F32: Verdict
A33: TP across nodes | B33: =E16 -> 35.87143 | C33: =E16/E8 -> 2.8839696 | D33: =E13 -> 128 | E33: 128 collectives/token (latency-bound) | F33: Avoid — doubles GPUs, slows each token
A34: PP across nodes | B34: =E23 -> 14.000629 | C34: =E23/E8 -> 1.1256141 | D34: =E20 -> 1 | E34: (stages-1) P2P sends/token | F34: Workable if model must span nodes + high concurrency
A35: DP / replication | B35: =E28 -> 12.438214 | C35: =E28/E8 -> 1 | D35: =0 -> 0 | E35: 0 (route at request level) | F35: Best fit — model fits per node, linear throughput
A37: Model notes & assumptions to validate
A38: 1) BANDWIDTH-BOUND BASELINE: A3 assumes decode is HBM-bandwidth-bound (true at the batch sizes here — see the Decode BW sheet's roofline verdict). If batching pushes decode compute-bound, substitute the compute-bound step time instead. 2) TP-ACROSS-NODES IS LATENCY-BOUND: the all-reduce message is tiny (B x 1 x hidden), so the bandwidth term is negligible and the 2(TP-1) x latency term dominates, paid 128x per token. This is why inter-node TP wrecks TPOT even on a fast-bandwidth fabric — latency, not bandwidth, is the killer. 3) PP BUBBLE MODEL is a first-order (stages-1)/microbatches approximation; real bubble depends on scheduler and request arrival. Raise 'In-flight microbatches' to see it shrink. 4) DP ASSUMES THE MODEL FITS PER NODE — true for Qwen3.8-27B (55.6 GB BF16 weights fit one 80GB GPU). For node-busting models (Kimi K3, large DeepSeek V4) DP-per-node is impossible and expert parallelism across nodes changes this analysis entirely. 5) HYBRID-ARCHITECTURE STICKINESS: the 48 DeltaNet layers hold a fixed-size RECURRENT STATE that is the sequence's memory and cannot be cheaply recomputed. Any scheme that migrates a sequence between nodes mid-generation (DP load-balancing, or a prefill->decode disaggregation handoff) must transfer BOTH the KV cache (16 layers) AND the recurrent state (48 layers). The state is fixed-size (transfer cost doesn't grow with context) but mandatory to move -> a decoding request develops strong node affinity. 6) DISAGGREGATION (Dynamo): not modeled as a row here, but the inter-node cost becomes a single bulk KV+state transfer at the prefill->decode handoff rather than 128 per-token collectives — which suits a slow fabric. The hybrid design SHRINKS that handoff (fixed-size state for 48 layers vs a full growing cache for all 64 in a same-size dense transformer).

Sheet Decode BW
A1: Decode Bandwidth / Roofline Calculation (per token-generation step)
A2: Decode throughput is usually dictated by HBM bandwidth, not FLOPS. Bytes are normalized to GB (1e9); compute is normalized to TFLOP. Arithmetic intensity and the ridge point are both expressed in TFLOP/GB — a pure ratio, so no unit-conversion constants are needed anywhere on this sheet.
A4: # | B4: Component | C4: Description | D4: Algebraic Formula | E4: Value | F4: Unit | G4: Notes / Source
A5: 1 | B5: Bytes — model weights | C5: Entire weight set must be streamed from HBM once per step, regardless of batch size, to produce any output | D5: N x weight_dtype_bytes / 1e9 | E5: =Params*WeightBytes/1000000000 -> 55.6 | F5: GB/step | G5: Batching amortizes this read across B tokens — the core lever for decode throughput
A6: 2 | B6: Bytes — KV cache read (full-attention, 16 layers) | C6: Growing K/V cache must be read back from HBM at every step for the 16 full-attention layers | D6: 2 x kv_heads x head_dim x kv_bytes x full_attn_layers x L_ctx x B / 1e9 | E6: =2*KvHeads*HeadDim*KVBytes*FullAttnLayers*DecodeContextLen*Concurrency/1000000000 -> 4.2954916 | F6: GB/step | G6: Scales with context length AND concurrency — the classic KV-cache bandwidth tax
A7: 3 | B7: Bytes — DeltaNet state read (48 layers) | C7: Fixed-size recurrent state read per sequence — independent of context length | D7: v_heads x head_dim^2 x kv_bytes x delta_layers x B / 1e9 | E7: =VHeads*DHeadDim^2*KVBytes*DeltaNetLayers*Concurrency/1000000000 -> 0.60397978 | F7: GB/step | G7: Second bandwidth saving of the hybrid design, layered on top of the FLOP saving
A8: 4 | B8: TOTAL BYTES MOVED / step | C8: Sum of rows 1-3 | D8: row1 + row2 + row3 | E8: =E5+E6+E7 -> 60.499471 | F8: GB/step
A9: 5 | B9: Arithmetic intensity | C9: TFLOP moved per GB — the key roofline metric. Cross-references TOTAL DECODE COMPUTE from the 'Decode TFLOPs' sheet. Because both numerator (TFLOP) and denominator (GB) already carry the same 1e12/1e9 scaling as PeakTFLOPS and BandwidthGBs, this ratio compares directly against the ridge point below with no extra conversion. | D9: total_decode_TFLOP / total_GB | E9: ='Decode TFLOPs'!E8/E8 -> 0.0075900899 | F9: TFLOP/GB | G9: Numerator pulled from 'Decode TFLOPs' sheet, row 4 (TOTAL DECODE COMPUTE / step)
A10: 6 | B10: GPU ridge point | C10: The compute:bandwidth crossover — below this intensity, a GPU is bandwidth-bound; above it, compute-bound. Peak TFLOPS / bandwidth GB/s reduces cleanly to TFLOP/GB — the 'per second' on both sides cancels. | D10: peak_TFLOPS / bandwidth_GBs | E10: =PeakTFLOPS/BandwidthGBs -> 0.30180921 | F10: TFLOP/GB | G10: H100 SXM5 default: 989 TFLOPS / 3,350 GB/s = ~0.30 TFLOP/GB
A11: 7 | B11: Regime verdict | C11: IF intensity < ridge point -> memory-bandwidth-bound, else compute-bound | D11: IF(intensity < ridge_point, "Memory-bound", "Compute-bound") | E11: =IF(E9<E10,"Memory-bound","Compute-bound") -> Memory-bound | F11: — | G11: Raise Concurrency to push intensity up toward (or past) the ridge point
A12: 8 | B12: Time — bandwidth-bound | C12: Time to move total bytes at the GPU's HBM bandwidth. GB / (GB/s) = seconds directly. | D12: total_GB / bandwidth_GBs | E12: =E8/BandwidthGBs -> 0.099505709 | F12: seconds
A13: 9 | B13: Time — compute-bound | C13: Pulled directly from the 'Decode TFLOPs' sheet (row 5: Estimated compute time / step) | D13: Decode TFLOPs!compute_time (row 5) | E13: ='Decode TFLOPs'!E9 -> 0.003574904 | F13: seconds | G13: Cross-sheet link — will move if Efficiency, PeakTFLOPS or FLOP terms change
A14: 10 | B14: Step time (binding constraint) | C14: The larger of the two candidate times is the real bottleneck | D14: MAX(bandwidth_time, compute_time) | E14: =MAX(E12,E13) -> 0.099505709 | F14: seconds
A15: 11 | B15: Estimated decode throughput | C15: Tokens generated per second across the whole batch, at the binding step time | D15: concurrency / step_time | E15: =Concurrency/E14 -> 80.397397 | F15: tokens/sec
A17: Roofline model — assumptions to validate
A18: 1) Weight bytes are counted once per step regardless of batch size B — correct only if all B sequences share the same resident weights in one batched kernel launch (true for standard continuous batching, not for pipeline-bubble edge cases). 2) KV-cache and DeltaNet-state bytes scale linearly with B, i.e. each sequence's cache is read independently — no cross-request sharing/prefix-caching benefit is modeled here; RadixAttention-style sharing would reduce the KV-read term. 3) The compute-bound time (row 9) uses the same 'Efficiency' fudge factor as prefill; decode kernels typically run at lower efficiency than prefill due to smaller per-kernel work, so treat the compute-bound estimate as optimistic. 4) 'Arithmetic intensity' and 'ridge point' are expressed here in TFLOP/GB rather than the textbook FLOP/Byte — the ratio and the memory-bound/compute-bound comparison are identical either way; only the absolute number's scale differs (by exactly 1000x), chosen for unit consistency with the rest of this workbook. 5) Selected silicon's precision (BF16/FP8/FP4) is chosen on the Model Architecture sheet — if running FP8 compute, switch it there for a tighter estimate; PeakTFLOPS updates automatically.
